Workbook

Sheet Base_Dados
A1: ID | B1: Data | C1: Semana_ISO | D1: Mês | E1: Ano | F1: Cliente | G1: Tipo_Treinamento | H1: Instrutor | I1: Supervisor | J1: Turma | K1: Participantes | L1: Presenças | M1: Faltas | N1: % Presença | O1: Avaliação (0-10) | P1: Indicador | Q1: Antes | R1: Depois | S1: Janela (dias) | T1: Observações | U1: Evolução % | V1: Impacto_Pos (0/1) | W1: KPI Negócio | X1: Valor Antes | Y1: Valor D+7 | Z1: Valor D+15 | AA1: Valor D+30 | AB1: Impacto %
A2: (preencher) | B2: (data) | C2: (auto) | D2: (auto) | E2: (auto) | F2: (lista) | G2: (lista) | H2: (lista) | I2: (lista) | J2: (texto) | K2: (n) | L2: (n) | M2: (auto) | N2: (auto) | O2: (n) | P2: (lista) | Q2: (n) | R2: (n) | S2: 7/15/30 | T2: Opcional | U2: (auto) | V2: (auto)
A3: 1 | B3: 46005 | C3: =_xlfn.ISOWEEKNUM(tbl_TD[[#This Row],[Data]]) -> 50 | D3: =MONTH(B3) -> 12 | E3: =YEAR(B3) -> 2025 | F3: MERCANTIL | G3: Av. Técnica | H3: Sarah Almeida | I3: Zaina Doria | K3: 30 | L3: 30 | N3: =IFERROR(L3/K3,0) -> 1 | U3: =IFERROR((R3-Q3)/Q3,0) -> 0 | V3: =IF(R3>Q3,1,0) -> 0
A4: 2 | B4: 46038 | C4: =_xlfn.ISOWEEKNUM(tbl_TD[[#This Row],[Data]]) -> 3 | D4: =MONTH(B4) -> 1 | E4: =YEAR(B4) -> 2026 | F4: MERCANTIL | G4: Av. Técnica | H4: Laiane Santos | I4: Zaina Doria | K4: 45 | L4: 45 | N4: =IFERROR(L4/K4,0) -> 1 | U4: =IFERROR((R4-Q4)/Q4,0) -> 0 | V4: =IF(R4>Q4,1,0) -> 0
A5: 3 | B5: 46049 | C5: =_xlfn.ISOWEEKNUM(tbl_TD[[#This Row],[Data]]) -> 5 | D5: =MONTH(B5) -> 1 | E5: =YEAR(B5) -> 2026 | F5: MERCANTIL | G5: Av. Técnica | H5: Fabiane Almeida | I5: Zaina Doria | K5: 8 | L5: 8 | N5: =IFERROR(L5/K5,0) -> 1 | U5: =IFERROR((R5-Q5)/Q5,0) -> 0 | V5: =IF(R5>Q5,1,0) -> 0
A6: 4 | B6: 46045 | C6: =_xlfn.ISOWEEKNUM(tbl_TD[[#This Row],[Data]]) -> 4 | D6: =MONTH(B6) -> 1 | E6: =YEAR(B6) -> 2026 | F6: Prefeitura de Salvador | G6: Av. Técnica | H6: Wilze Oliveira | I6: Amilis Oliveira | K6: 11 | L6: 11 | N6: =IFERROR(L6/K6,0) -> 1 | U6: =IFERROR((R6-Q6)/Q6,0) -> 0 | V6: =IF(R6>Q6,1,0) -> 0
A7: 5 | B7: 46055 | C7: =_xlfn.ISOWEEKNUM(tbl_TD[[#This Row],[Data]]) -> 6 | D7: =MONTH(B7) -> 2 | E7: =YEAR(B7) -> 2026 | F7: Agibank | G7: Av. Técnica | H7: Etilaine Souza | I7: Amilis Oliveira | K7: 21 | L7: 21 | N7: =IFERROR(L7/K7,0) -> 1 | U7: =IFERROR((R7-Q7)/Q7,0) -> 0 | V7: =IF(R7>Q7,1,0) -> 0
A8: 6 | B8: 46077 | C8: =_xlfn.ISOWEEKNUM(tbl_TD[[#This Row],[Data]]) -> 9 | D8: =MONTH(B8) -> 2 | E8: =YEAR(B8) -> 2026 | F8: Claro | G8: Av. Técnica | H8: Diogo Silva | I8: Zaina Doria | K8: 6 | L8: 6 | N8: =IFERROR(L8/K8,0) -> 1 | U8: =IFERROR((R8-Q8)/Q8,0) -> 0 | V8: =IF(R8>Q8,1,0) -> 0
A9: 7 | B9: 46077 | C9: =_xlfn.ISOWEEKNUM(tbl_TD[[#This Row],[Data]]) -> 9 | D9: =MONTH(B9) -> 2 | E9: =YEAR(B9) -> 2026 | F9: Claro | G9: Av. Técnica | H9: Evelin Rocha | I9: Zaina Doria | K9: 17 | L9: 17 | N9: =IFERROR(L9/K9,0) -> 1 | U9: =IFERROR((R9-Q9)/Q9,0) -> 0 | V9: =IF(R9>Q9,1,0) -> 0
A10: 8 | B10: 46071 | C10: =_xlfn.ISOWEEKNUM(tbl_TD[[#This Row],[Data]]) -> 8 | D10: =MONTH(B10) -> 2 | E10: =YEAR(B10) -> 2026 | F10: Buser | G10: Av. Técnica | H10: Leticia Ramos | I10: Zaina Doria | K10: 9 | L10: 9 | N10: =IFERROR(L10/K10,0) -> 1 | U10: =IFERROR((R10-Q10)/Q10,0) -> 0 | V10: =IF(R10>Q10,1,0) -> 0
A11: 9 | B11: 46059 | C11: =_xlfn.ISOWEEKNUM(tbl_TD[[#This Row],[Data]]) -> 6 | D11: =MONTH(B11) -> 2 | E11: =YEAR(B11) -> 2026 | F11: Mercantil | G11: Produto | H11: Sarah Almeida | I11: Zaina Doria | J11: REPOSIÇÃO ENTREGUES COM 5 DIAS | K11: 29 | L11: 29 | N11: =IFERROR(L11/K11,0) -> 1 | U11: =IFERROR((R11-Q11)/Q11,0) -> 0 | V11: =IF(R11>Q11,1,0) -> 0
A12: 10 | B12: 46071 | C12: =_xlfn.ISOWEEKNUM(tbl_TD[[#This Row],[Data]]) -> 8 | D12: =MONTH(B12) -> 2 | E12: =YEAR(B12) -> 2026 | F12: Mercantil | G12: Reciclagem | H12: Laiane Santos | I12: Zaina Doria | J12: FCR/ÓBITO | K12: 179 | L12: 145 | M12: 34 | N12: =IFERROR(L12/K12,0) -> 0.81005587 | U12: =IFERROR((R12-Q12)/Q12,0) -> 0 | V12: =IF(R12>Q12,1,0) -> 0
A13: 11 | B13: 46094 | C13: =_xlfn.ISOWEEKNUM(tbl_TD[[#This Row],[Data]]) -> 11 | D13: =MONTH(B13) -> 3 | E13: =YEAR(B13) -> 2026 | F13: Mercantil | G13: Reciclagem | H13: Fabiane Almeida | I13: Zaina Doria | J13: Reciclagem Retenção MEU+ | K13: 10 | L13: 10 | N13: =IFERROR(L13/K13,0) -> 1 | U13: =IFERROR((R13-Q13)/Q13,0) -> 0 | V13: =IF(R13>Q13,1,0) -> 0
A14: 12 | B14: 46064 | C14: =_xlfn.ISOWEEKNUM(tbl_TD[[#This Row],[Data]]) -> 7 | D14: =MONTH(B14) -> 2 | E14: =YEAR(B14) -> 2026 | F14: Agibank | G14: Av. Técnica | H14: Hiago Amor | I14: Amilis Oliveira | K14: 32 | L14: 29 | M14: 3 | N14: =IFERROR(L14/K14,0) -> 0.90625 | U14: =IFERROR((R14-Q14)/Q14,0) -> 0 | V14: =IF(R14>Q14,1,0) -> 0
A15: 13 | B15: 46055 | C15: =_xlfn.ISOWEEKNUM(tbl_TD[[#This Row],[Data]]) -> 6 | D15: =MONTH(B15) -> 2 | E15: =YEAR(B15) -> 2026 | F15: Rede Américas | G15: Reciclagem | H15: Wilze Oliveira | I15: Amilis Oliveira | K15: 3 | L15: 3 | N15: =IFERROR(L15/K15,0) -> 1 | U15: =IFERROR((R15-Q15)/Q15,0) -> 0 | V15: =IF(R15>Q15,1,0) -> 0
A16: 14 | B16: 46062 | C16: =_xlfn.ISOWEEKNUM(tbl_TD[[#This Row],[Data]]) -> 7 | D16: =MONTH(B16) -> 2 | E16: =YEAR(B16) -> 2026 | F16: Rede Américas | G16: Av. Técnica | H16: Wilze Oliveira | I16: Amilis Oliveira | K16: 31 | L16: 31 | N16: =IFERROR(L16/K16,0) -> 1 | U16: =IFERROR((R16-Q16)/Q16,0) -> 0 | V16: =IF(R16>Q16,1,0) -> 0
A17: 15 | B17: 46032 | C17: =_xlfn.ISOWEEKNUM(tbl_TD[[#This Row],[Data]]) -> 2 | D17: =MONTH(B17) -> 1 | E17: =YEAR(B17) -> 2026 | F17: Agibank | G17: Reciclagem | H17: Etilaine Souza | I17: Amilis Oliveira | J17: Desaverbação/CP não domiciliado+Seguro prestamista+Diversidade Etária | K17: 271 | L17: 271 | N17: =IFERROR(L17/K17,0) -> 1 | U17: =IFERROR((R17-Q17)/Q17,0) -> 0 | V17: =IF(R17>Q17,1,0) -> 0
A18: 16 | B18: 46062 | C18: =_xlfn.ISOWEEKNUM(tbl_TD[[#This Row],[Data]]) -> 7 | D18: =MONTH(B18) -> 2 | E18: =YEAR(B18) -> 2026 | F18: Agibank | G18: Reciclagem | H18: Alessandra Ferreira | I18: Amilis Oliveira | J18: Atualiza AGI | K18: 223 | L18: 223 | N18: =IFERROR(L18/K18,0) -> 1 | U18: =IFERROR((R18-Q18)/Q18,0) -> 0 | V18: =IF(R18>Q18,1,0) -> 0
A19: 17 | C19: =_xlfn.ISOWEEKNUM(tbl_TD[[#This Row],[Data]]) -> 52 | D19: =MONTH(B19) -> 1 | E19: =YEAR(B19) -> 1900 | N19: =IFERROR(L19/K19,0) -> 0 | U19: =IFERROR((R19-Q19)/Q19,0) -> 0 | V19: =IF(R19>Q19,1,0) -> 0
A20: 18 | C20: =_xlfn.ISOWEEKNUM(tbl_TD[[#This Row],[Data]]) -> 52 | D20: =MONTH(B20) -> 1 | E20: =YEAR(B20) -> 1900 | N20: =IFERROR(L20/K20,0) -> 0 | U20: =IFERROR((R20-Q20)/Q20,0) -> 0 | V20: =IF(R20>Q20,1,0) -> 0
A21: 19 | C21: =_xlfn.ISOWEEKNUM(tbl_TD[[#This Row],[Data]]) -> 52 | D21: =MONTH(B21) -> 1 | E21: =YEAR(B21) -> 1900 | N21: =IFERROR(L21/K21,0) -> 0 | U21: =IFERROR((R21-Q21)/Q21,0) -> 0 | V21: =IF(R21>Q21,1,0) -> 0
A22: 20 | C22: =_xlfn.ISOWEEKNUM(tbl_TD[[#This Row],[Data]]) -> 52 | D22: =MONTH(B22) -> 1 | E22: =YEAR(B22) -> 1900 | N22: =IFERROR(L22/K22,0) -> 0 | U22: =IFERROR((R22-Q22)/Q22,0) -> 0 | V22: =IF(R22>Q22,1,0) -> 0
A23: 21 | C23: =_xlfn.ISOWEEKNUM(tbl_TD[[#This Row],[Data]]) -> 52 | D23: =MONTH(B23) -> 1 | E23: =YEAR(B23) -> 1900 | N23: =IFERROR(L23/K23,0) -> 0 | U23: =IFERROR((R23-Q23)/Q23,0) -> 0 | V23: =IF(R23>Q23,1,0) -> 0
A24: 22 | C24: =_xlfn.ISOWEEKNUM(tbl_TD[[#This Row],[Data]]) -> 52 | D24: =MONTH(B24) -> 1 | E24: =YEAR(B24) -> 1900 | N24: =IFERROR(L24/K24,0) -> 0 | U24: =IFERROR((R24-Q24)/Q24,0) -> 0 | V24: =IF(R24>Q24,1,0) -> 0
A25: 23 | C25: =_xlfn.ISOWEEKNUM(tbl_TD[[#This Row],[Data]]) -> 52 | D25: =MONTH(B25) -> 1 | E25: =YEAR(B25) -> 1900 | N25: =IFERROR(L25/K25,0) -> 0 | U25: =IFERROR((R25-Q25)/Q25,0) -> 0 | V25: =IF(R25>Q25,1,0) -> 0
A26: 24 | C26: =_xlfn.ISOWEEKNUM(tbl_TD[[#This Row],[Data]]) -> 52 | D26: =MONTH(B26) -> 1 | E26: =YEAR(B26) -> 1900 | N26: =IFERROR(L26/K26,0) -> 0 | U26: =IFERROR((R26-Q26)/Q26,0) -> 0 | V26: =IF(R26>Q26,1,0) -> 0
A27: 25 | C27: =_xlfn.ISOWEEKNUM(tbl_TD[[#This Row],[Data]]) -> 52 | D27: =MONTH(B27) -> 1 | E27: =YEAR(B27) -> 1900 | N27: =IFERROR(L27/K27,0) -> 0 | U27: =IFERROR((R27-Q27)/Q27,0) -> 0 | V27: =IF(R27>Q27,1,0) -> 0
A28: 26 | C28: =_xlfn.ISOWEEKNUM(tbl_TD[[#This Row],[Data]]) -> 52 | D28: =MONTH(B28) -> 1 | E28: =YEAR(B28) -> 1900 | N28: =IFERROR(L28/K28,0) -> 0 | U28: =IFERROR((R28-Q28)/Q28,0) -> 0 | V28: =IF(R28>Q28,1,0) -> 0
A29: 27 | C29: =_xlfn.ISOWEEKNUM(tbl_TD[[#This Row],[Data]]) -> 52 | D29: =MONTH(B29) -> 1 | E29: =YEAR(B29) -> 1900 | N29: =IFERROR(L29/K29,0) -> 0 | U29: =IFERROR((R29-Q29)/Q29,0) -> 0 | V29: =IF(R29>Q29,1,0) -> 0
A30: 28 | C30: =_xlfn.ISOWEEKNUM(tbl_TD[[#This Row],[Data]]) -> 52 | D30: =MONTH(B30) -> 1 | E30: =YEAR(B30) -> 1900 | N30: =IFERROR(L30/K30,0) -> 0 | U30: =IFERROR((R30-Q30)/Q30,0) -> 0 | V30: =IF(R30>Q30,1,0) -> 0
... A62: 60 | C62: =_xlfn.ISOWEEKNUM(tbl_TD[[#This Row],[Data]]) -> 52 | D62: =MONTH(B62) -> 1 | E62: =YEAR(B62) -> 1900 | N62: =IFERROR(L62/K62,0) -> 0 | U62: =IFERROR((R62-Q62)/Q62,0) -> 0 | V62: =IF(R62>Q62,1,0) -> 0

Sheet Dimensoes
A1: Listas para validação
A2: Cliente | B2: Tipo_Treinamento | C2: KPIs_Negocio | D2: Instrutor | E2: Supervisor | F2: Indicador | G2: Ano
A3: Todos | B3: Todos | C3: Qualidade | D3: Todos | E3: Todos | F3: Todos | G3: 2026
A4: Claro | B4: Reciclagem | C4: TMA | D4: Evelin Rocha | E4: Amilis Oliveira | F4: Qualidade | G4: 2027
A5: Mercantil | B5: Atualização | C5: Conversão | D5: Laiane Santos | E5: Zaina Doria | F5: TMA | G5: 2028
A6: Agibank | B6: Produto | C6: NPS Operacional | D6: Leticia Ramos | F6: Conversao | G6: 2029
A7: Rede Américas | B7: Qualidade | C7: Absenteísmo | D7: Hiago Amor | F7: NPS | G7: 2030
A8: Buser | B8: Comportamental | D8: Maricelia Santos
A9: Crea | B9: Processos | D9: Diogo Silva
A10: Prefeitura de Salvador | B10: Tecnologia | D10: Fabiane Almeida
A11: Hugsnet | B11: Av. Técnica | D11: Sarah Almeida
B12: Celula Baby | D12: Alessandra Ferreira
D13: Wilze Oliveira
D14: Etilaine Souza

Sheet Dashboard_Semanal
A1: Dashboard T&D — Semanal
A3: Filtros | D3: Critérios (auto) | E3: =COUNTIFS(Base_Dados!$B$3:$B$2000,">="&D4,Base_Dados!$B$3:$B$2000,"<="&D5,Base_Dados!$F$3:$F$2000,D6,Base_Dados!$G$3:$G$2000,D7,Base_Dados!$H$3:$H$2000,D8,Base_Dados!$I$3:$I$2000,D9) -> 10 | G3: =SUMIFS(Base_Dados!$L$3:$L$2000,Base_Dados!$B$3:$B$2000,">="&D4,Base_Dados!$B$3:$B$2000,"<="&D5,Base_Dados!$F$3:$F$2000,D6,Base_Dados!$G$3:$G$2000,D7,Base_Dados!$H$3:$H$2000,D8,Base_Dados!$I$3:$I$2000,D9) -> 513 | I3: =IFERROR(SUMIFS(Base_Dados!$L$3:$L$2000,Base_Dados!$B$3:$B$2000,">="&D4,Base_Dados!$B$3:$B$2000,"<="&D5,Base_Dados!$F$3:$F$2000,D6,Base_Dados!$G$3:$G$2000,D7,Base_Dados!$H$3:$H$2000,D8,Base_Dados!$I$3:$I$2000,D9)/SUMIFS(Base_Dados!$K$3:$K$2000,Base_Dados!$B$3:$B$2000,">="&D4,Base_Dados!$B$3:$B$2000,"<="&D5,Base_Dados!$F$3:$F$2000,D6,Base_Dados!$G$3:$G$2000,D7,Base_Dados!$H$3:$H$2000,D8,Base_Dados!$I$3:$I$2000,D9),0) -> 0.93272727
A4: Data inicial | B4: 46054 | D4: =B4 -> 46054 | E4: Treinamentos | G4: Colab. treinados (presenças) | I4: % presença
A5: Data final | B5: 46081 | D5: =B5 -> 46081 | E5: =IFERROR(AVERAGEIFS(Base_Dados!$O$3:$O$2000,Base_Dados!$B$3:$B$2000,">="&D4,Base_Dados!$B$3:$B$2000,"<="&D5,Base_Dados!$F$3:$F$2000,D6,Base_Dados!$G$3:$G$2000,D7,Base_Dados!$H$3:$H$2000,D8,Base_Dados!$I$3:$I$2000,D9),0) -> 0 | G5: =IFERROR(AVERAGEIFS(Base_Dados!$U$3:$U$2000,Base_Dados!$B$3:$B$2000,">="&D4,Base_Dados!$B$3:$B$2000,"<="&D5,Base_Dados!$F$3:$F$2000,D6,Base_Dados!$G$3:$G$2000,D7,Base_Dados!$H$3:$H$2000,D8,Base_Dados!$I$3:$I$2000,D9,Base_Dados!$P$3:$P$2000,D10),0) -> 0 | I5: =IFERROR(SUMIFS(Base_Dados!$V$3:$V$2000,Base_Dados!$B$3:$B$2000,">="&D4,Base_Dados!$B$3:$B$2000,"<="&D5,Base_Dados!$F$3:$F$2000,D6,Base_Dados!$G$3:$G$2000,D7,Base_Dados!$H$3:$H$2000,D8,Base_Dados!$I$3:$I$2000,D9,Base_Dados!$P$3:$P$2000,D10)/COUNTIFS(Base_Dados!$B$3:$B$2000,">="&D4,Base_Dados!$B$3:$B$2000,"<="&D5,Base_Dados!$F$3:$F$2000,D6,Base_Dados!$G$3:$G$2000,D7,Base_Dados!$H$3:$H$2000,D8,Base_Dados!$I$3:$I$2000,D9),0) -> 0
A6: Cliente | B6: Todos | D6: =IF(B6="Todos","*",B6) -> * | E6: Nota média | G6: Evolução média (indicador) | I6: % turmas c/ impacto +
A7: Tipo de Treinamento | B7: Todos | D7: =IF(B7="Todos","*",B7) -> *
A8: Instrutor | B8: Todos | D8: =IF(B8="Todos","*",B8) -> *
A9: Supervisor | B9: Todos | D9: =IF(B9="Todos","*",B9) -> *
A10: Indicador (para efetividade) | B10: Todos | D10: =IF(B10="Todos","*",B10) -> *
A13: Resumo diário
A14: Data | B14: Treinamentos | C14: Presenças
A15: =$B4+0 -> 46054 | B15: =COUNTIFS(Base_Dados!$B$3:$B$2000,A15,Base_Dados!$F$3:$F$2000,D6,Base_Dados!$G$3:$G$2000,D7,Base_Dados!$H$3:$H$2000,D8,Base_Dados!$I$3:$I$2000,D9) -> 0 | C15: =SUMIFS(Base_Dados!$L$3:$L$2000,Base_Dados!$B$3:$B$2000,A15,Base_Dados!$F$3:$F$2000,D6,Base_Dados!$G$3:$G$2000,D7,Base_Dados!$H$3:$H$2000,D8,Base_Dados!$I$3:$I$2000,D9) -> 0
A16: =$B4+1 -> 46055 | B16: =COUNTIFS(Base_Dados!$B$3:$B$2000,A16,Base_Dados!$F$3:$F$2000,D6,Base_Dados!$G$3:$G$2000,D7,Base_Dados!$H$3:$H$2000,D8,Base_Dados!$I$3:$I$2000,D9) -> 2 | C16: =SUMIFS(Base_Dados!$L$3:$L$2000,Base_Dados!$B$3:$B$2000,A16,Base_Dados!$F$3:$F$2000,D6,Base_Dados!$G$3:$G$2000,D7,Base_Dados!$H$3:$H$2000,D8,Base_Dados!$I$3:$I$2000,D9) -> 24
A17: =$B4+2 -> 46056 | B17: =COUNTIFS(Base_Dados!$B$3:$B$2000,A17,Base_Dados!$F$3:$F$2000,D6,Base_Dados!$G$3:$G$2000,D7,Base_Dados!$H$3:$H$2000,D8,Base_Dados!$I$3:$I$2000,D9) -> 0 | C17: =SUMIFS(Base_Dados!$L$3:$L$2000,Base_Dados!$B$3:$B$2000,A17,Base_Dados!$F$3:$F$2000,D6,Base_Dados!$G$3:$G$2000,D7,Base_Dados!$H$3:$H$2000,D8,Base_Dados!$I$3:$I$2000,D9) -> 0
A18: =$B4+3 -> 46057 | B18: =COUNTIFS(Base_Dados!$B$3:$B$2000,A18,Base_Dados!$F$3:$F$2000,D6,Base_Dados!$G$3:$G$2000,D7,Base_Dados!$H$3:$H$2000,D8,Base_Dados!$I$3:$I$2000,D9) -> 0 | C18: =SUMIFS(Base_Dados!$L$3:$L$2000,Base_Dados!$B$3:$B$2000,A18,Base_Dados!$F$3:$F$2000,D6,Base_Dados!$G$3:$G$2000,D7,Base_Dados!$H$3:$H$2000,D8,Base_Dados!$I$3:$I$2000,D9) -> 0
A19: =$B4+4 -> 46058 | B19: =COUNTIFS(Base_Dados!$B$3:$B$2000,A19,Base_Dados!$F$3:$F$2000,D6,Base_Dados!$G$3:$G$2000,D7,Base_Dados!$H$3:$H$2000,D8,Base_Dados!$I$3:$I$2000,D9) -> 0 | C19: =SUMIFS(Base_Dados!$L$3:$L$2000,Base_Dados!$B$3:$B$2000,A19,Base_Dados!$F$3:$F$2000,D6,Base_Dados!$G$3:$G$2000,D7,Base_Dados!$H$3:$H$2000,D8,Base_Dados!$I$3:$I$2000,D9) -> 0
A20: =$B4+5 -> 46059 | B20: =COUNTIFS(Base_Dados!$B$3:$B$2000,A20,Base_Dados!$F$3:$F$2000,D6,Base_Dados!$G$3:$G$2000,D7,Base_Dados!$H$3:$H$2000,D8,Base_Dados!$I$3:$I$2000,D9) -> 1 | C20: =SUMIFS(Base_Dados!$L$3:$L$2000,Base_Dados!$B$3:$B$2000,A20,Base_Dados!$F$3:$F$2000,D6,Base_Dados!$G$3:$G$2000,D7,Base_Dados!$H$3:$H$2000,D8,Base_Dados!$I$3:$I$2000,D9) -> 29
A21: =$B4+6 -> 46060 | B21: =COUNTIFS(Base_Dados!$B$3:$B$2000,A21,Base_Dados!$F$3:$F$2000,D6,Base_Dados!$G$3:$G$2000,D7,Base_Dados!$H$3:$H$2000,D8,Base_Dados!$I$3:$I$2000,D9) -> 0 | C21: =SUMIFS(Base_Dados!$L$3:$L$2000,Base_Dados!$B$3:$B$2000,A21,Base_Dados!$F$3:$F$2000,D6,Base_Dados!$G$3:$G$2000,D7,Base_Dados!$H$3:$H$2000,D8,Base_Dados!$I$3:$I$2000,D9) -> 0
A23: Treinamentos por tipo
A24: Tipo | B24: Treinamentos
A25: Inicial | B25: =COUNTIFS(Base_Dados!$B$3:$B$2000,">="&D4,Base_Dados!$B$3:$B$2000,"<="&D5,Base_Dados!$F$3:$F$2000,D6,Base_Dados!$G$3:$G$2000,"Inicial",Base_Dados!$H$3:$H$2000,D8,Base_Dados!$I$3:$I$2000,D9) -> 0
A26: Reciclagem | B26: =COUNTIFS(Base_Dados!$B$3:$B$2000,">="&D4,Base_Dados!$B$3:$B$2000,"<="&D5,Base_Dados!$F$3:$F$2000,D6,Base_Dados!$G$3:$G$2000,"Reciclagem",Base_Dados!$H$3:$H$2000,D8,Base_Dados!$I$3:$I$2000,D9) -> 3
A27: Atualização | B27: =COUNTIFS(Base_Dados!$B$3:$B$2000,">="&D4,Base_Dados!$B$3:$B$2000,"<="&D5,Base_Dados!$F$3:$F$2000,D6,Base_Dados!$G$3:$G$2000,"Atualização",Base_Dados!$H$3:$H$2000,D8,Base_Dados!$I$3:$I$2000,D9) -> 0
A28: Produto | B28: =COUNTIFS(Base_Dados!$B$3:$B$2000,">="&D4,Base_Dados!$B$3:$B$2000,"<="&D5,Base_Dados!$F$3:$F$2000,D6,Base_Dados!$G$3:$G$2000,"Produto",Base_Dados!$H$3:$H$2000,D8,Base_Dados!$I$3:$I$2000,D9) -> 1
A29: Qualidade | B29: =COUNTIFS(Base_Dados!$B$3:$B$2000,">="&D4,Base_Dados!$B$3:$B$2000,"<="&D5,Base_Dados!$F$3:$F$2000,D6,Base_Dados!$G$3:$G$2000,"Qualidade",Base_Dados!$H$3:$H$2000,D8,Base_Dados!$I$3:$I$2000,D9) -> 0
A30: Comportamental | B30: =COUNTIFS(Base_Dados!$B$3:$B$2000,">="&D4,Base_Dados!$B$3:$B$2000,"<="&D5,Base_Dados!$F$3:$F$2000,D6,Base_Dados!$G$3:$G$2000,"Comportamental",Base_Dados!$H$3:$H$2000,D8,Base_Dados!$I$3:$I$2000,D9) -> 0
A31: Processos | B31: =COUNTIFS(Base_Dados!$B$3:$B$2000,">="&D4,Base_Dados!$B$3:$B$2000,"<="&D5,Base_Dados!$F$3:$F$2000,D6,Base_Dados!$G$3:$G$2000,"Processos",Base_Dados!$H$3:$H$2000,D8,Base_Dados!$I$3:$I$2000,D9) -> 0
A32: Tecnologia | B32: =COUNTIFS(Base_Dados!$B$3:$B$2000,">="&D4,Base_Dados!$B$3:$B$2000,"<="&D5,Base_Dados!$F$3:$F$2000,D6,Base_Dados!$G$3:$G$2000,"Tecnologia",Base_Dados!$H$3:$H$2000,D8,Base_Dados!$I$3:$I$2000,D9) -> 0
A35: Dica: preencha novos registros na aba Base_Dados (linhas a partir da 3). O dashboard atualiza automaticamente.

Sheet Dashboard_Mensal
A1: Dashboard T&D — Mensal
A3: Filtros | D3: Critérios (auto) | E3: =COUNTIFS(Base_Dados!$B$3:$B$2000,">="&D4,Base_Dados!$B$3:$B$2000,"<="&D5,Base_Dados!$F$3:$F$2000,D6,Base_Dados!$G$3:$G$2000,D7,Base_Dados!$H$3:$H$2000,D8,Base_Dados!$I$3:$I$2000,D9) -> 10 | G3: =SUMIFS(Base_Dados!$L$3:$L$2000,Base_Dados!$B$3:$B$2000,">="&D4,Base_Dados!$B$3:$B$2000,"<="&D5,Base_Dados!$F$3:$F$2000,D6,Base_Dados!$G$3:$G$2000,D7,Base_Dados!$H$3:$H$2000,D8,Base_Dados!$I$3:$I$2000,D9) -> 513 | I3: =IFERROR(SUMIFS(Base_Dados!$L$3:$L$2000,Base_Dados!$B$3:$B$2000,">="&D4,Base_Dados!$B$3:$B$2000,"<="&D5,Base_Dados!$F$3:$F$2000,D6,Base_Dados!$G$3:$G$2000,D7,Base_Dados!$H$3:$H$2000,D8,Base_Dados!$I$3:$I$2000,D9)/SUMIFS(Base_Dados!$K$3:$K$2000,Base_Dados!$B$3:$B$2000,">="&D4,Base_Dados!$B$3:$B$2000,"<="&D5,Base_Dados!$F$3:$F$2000,D6,Base_Dados!$G$3:$G$2000,D7,Base_Dados!$H$3:$H$2000,D8,Base_Dados!$I$3:$I$2000,D9),0) -> 0.93272727
A4: Data inicial | B4: 46054 | D4: =B4 -> 46054 | E4: Treinamentos | G4: Colab. treinados (presenças) | I4: % presença
A5: Data final | B5: 46081 | D5: =B5 -> 46081 | E5: =IFERROR(AVERAGEIFS(Base_Dados!$O$3:$O$2000,Base_Dados!$B$3:$B$2000,">="&D4,Base_Dados!$B$3:$B$2000,"<="&D5,Base_Dados!$F$3:$F$2000,D6,Base_Dados!$G$3:$G$2000,D7,Base_Dados!$H$3:$H$2000,D8,Base_Dados!$I$3:$I$2000,D9),0) -> 0 | G5: =IFERROR(AVERAGEIFS(Base_Dados!$U$3:$U$2000,Base_Dados!$B$3:$B$2000,">="&D4,Base_Dados!$B$3:$B$2000,"<="&D5,Base_Dados!$F$3:$F$2000,D6,Base_Dados!$G$3:$G$2000,D7,Base_Dados!$H$3:$H$2000,D8,Base_Dados!$I$3:$I$2000,D9,Base_Dados!$P$3:$P$2000,D10),0) -> 0 | I5: =IFERROR(SUMIFS(Base_Dados!$V$3:$V$2000,Base_Dados!$B$3:$B$2000,">="&D4,Base_Dados!$B$3:$B$2000,"<="&D5,Base_Dados!$F$3:$F$2000,D6,Base_Dados!$G$3:$G$2000,D7,Base_Dados!$H$3:$H$2000,D8,Base_Dados!$I$3:$I$2000,D9,Base_Dados!$P$3:$P$2000,D10)/COUNTIFS(Base_Dados!$B$3:$B$2000,">="&D4,Base_Dados!$B$3:$B$2000,"<="&D5,Base_Dados!$F$3:$F$2000,D6,Base_Dados!$G$3:$G$2000,D7,Base_Dados!$H$3:$H$2000,D8,Base_Dados!$I$3:$I$2000,D9),0) -> 0
A6: Cliente | B6: Todos | D6: =IF(B6="Todos","*",B6) -> * | E6: Nota média | G6: Evolução média (indicador) | I6: % turmas c/ impacto +
A7: Tipo de Treinamento | B7: Todos | D7: =IF(B7="Todos","*",B7) -> *
A8: Instrutor | B8: Todos | D8: =IF(B8="Todos","*",B8) -> *
A9: Supervisor | B9: Todos | D9: =IF(B9="Todos","*",B9) -> *
A10: Indicador (para efetividade) | B10: Todos | D10: =IF(B10="Todos","*",B10) -> *
A12: Obs.: Ajuste o filtro de datas para abranger o mês inteiro.
A13: Resumo por semana (7 dias)
A14: Semana | B14: Início | C14: Fim | D14: Treinamentos | E14: Nota média
A15: Semana 1 | B15: =B4+0 -> 46054 | C15: =B4+6 -> 46060 | D15: =COUNTIFS(Base_Dados!$B$3:$B$2000,">="&B15,Base_Dados!$B$3:$B$2000,"<="&C15,Base_Dados!$F$3:$F$2000,D6,Base_Dados!$G$3:$G$2000,D7,Base_Dados!$H$3:$H$2000,D8,Base_Dados!$I$3:$I$2000,D9) -> 3 | E15: =IFERROR(AVERAGEIFS(Base_Dados!$O$3:$O$2000,Base_Dados!$B$3:$B$2000,">="&B15,Base_Dados!$B$3:$B$2000,"<="&C15,Base_Dados!$F$3:$F$2000,D6,Base_Dados!$G$3:$G$2000,D7,Base_Dados!$H$3:$H$2000,D8,Base_Dados!$I$3:$I$2000,D9),0) -> 0
A16: Semana 2 | B16: =B4+7 -> 46061 | C16: =B4+13 -> 46067 | D16: =COUNTIFS(Base_Dados!$B$3:$B$2000,">="&B16,Base_Dados!$B$3:$B$2000,"<="&C16,Base_Dados!$F$3:$F$2000,D6,Base_Dados!$G$3:$G$2000,D7,Base_Dados!$H$3:$H$2000,D8,Base_Dados!$I$3:$I$2000,D9) -> 3 | E16: =IFERROR(AVERAGEIFS(Base_Dados!$O$3:$O$2000,Base_Dados!$B$3:$B$2000,">="&B16,Base_Dados!$B$3:$B$2000,"<="&C16,Base_Dados!$F$3:$F$2000,D6,Base_Dados!$G$3:$G$2000,D7,Base_Dados!$H$3:$H$2000,D8,Base_Dados!$I$3:$I$2000,D9),0) -> 0
A17: Semana 3 | B17: =B4+14 -> 46068 | C17: =B4+20 -> 46074 | D17: =COUNTIFS(Base_Dados!$B$3:$B$2000,">="&B17,Base_Dados!$B$3:$B$2000,"<="&C17,Base_Dados!$F$3:$F$2000,D6,Base_Dados!$G$3:$G$2000,D7,Base_Dados!$H$3:$H$2000,D8,Base_Dados!$I$3:$I$2000,D9) -> 2 | E17: =IFERROR(AVERAGEIFS(Base_Dados!$O$3:$O$2000,Base_Dados!$B$3:$B$2000,">="&B17,Base_Dados!$B$3:$B$2000,"<="&C17,Base_Dados!$F$3:$F$2000,D6,Base_Dados!$G$3:$G$2000,D7,Base_Dados!$H$3:$H$2000,D8,Base_Dados!$I$3:$I$2000,D9),0) -> 0
A18: Semana 4 | B18: =B4+21 -> 46075 | C18: =B4+27 -> 46081 | D18: =COUNTIFS(Base_Dados!$B$3:$B$2000,">="&B18,Base_Dados!$B$3:$B$2000,"<="&C18,Base_Dados!$F$3:$F$2000,D6,Base_Dados!$G$3:$G$2000,D7,Base_Dados!$H$3:$H$2000,D8,Base_Dados!$I$3:$I$2000,D9) -> 2 | E18: =IFERROR(AVERAGEIFS(Base_Dados!$O$3:$O$2000,Base_Dados!$B$3:$B$2000,">="&B18,Base_Dados!$B$3:$B$2000,"<="&C18,Base_Dados!$F$3:$F$2000,D6,Base_Dados!$G$3:$G$2000,D7,Base_Dados!$H$3:$H$2000,D8,Base_Dados!$I$3:$I$2000,D9),0) -> 0
A19: Semana 5 | B19: =B4+28 -> 46082 | C19: =B4+34 -> 46088 | D19: =COUNTIFS(Base_Dados!$B$3:$B$2000,">="&B19,Base_Dados!$B$3:$B$2000,"<="&C19,Base_Dados!$F$3:$F$2000,D6,Base_Dados!$G$3:$G$2000,D7,Base_Dados!$H$3:$H$2000,D8,Base_Dados!$I$3:$I$2000,D9) -> 0 | E19: =IFERROR(AVERAGEIFS(Base_Dados!$O$3:$O$2000,Base_Dados!$B$3:$B$2000,">="&B19,Base_Dados!$B$3:$B$2000,"<="&C19,Base_Dados!$F$3:$F$2000,D6,Base_Dados!$G$3:$G$2000,D7,Base_Dados!$H$3:$H$2000,D8,Base_Dados!$I$3:$I$2000,D9),0) -> 0
A23: Treinamentos por cliente
A24: Cliente | B24: Treinamentos
A25: Claro | B25: =COUNTIFS(Base_Dados!$B$3:$B$2000,">="&D4,Base_Dados!$B$3:$B$2000,"<="&D5,Base_Dados!$F$3:$F$2000,"Claro",Base_Dados!$G$3:$G$2000,D7,Base_Dados!$H$3:$H$2000,D8,Base_Dados!$I$3:$I$2000,D9) -> 2
A26: Mercantil | B26: =COUNTIFS(Base_Dados!$B$3:$B$2000,">="&D4,Base_Dados!$B$3:$B$2000,"<="&D5,Base_Dados!$F$3:$F$2000,"Mercantil",Base_Dados!$G$3:$G$2000,D7,Base_Dados!$H$3:$H$2000,D8,Base_Dados!$I$3:$I$2000,D9) -> 2
A27: Agibank | B27: =COUNTIFS(Base_Dados!$B$3:$B$2000,">="&D4,Base_Dados!$B$3:$B$2000,"<="&D5,Base_Dados!$F$3:$F$2000,"Agibank",Base_Dados!$G$3:$G$2000,D7,Base_Dados!$H$3:$H$2000,D8,Base_Dados!$I$3:$I$2000,D9) -> 3
A28: E-commerce | B28: =COUNTIFS(Base_Dados!$B$3:$B$2000,">="&D4,Base_Dados!$B$3:$B$2000,"<="&D5,Base_Dados!$F$3:$F$2000,"E-commerce",Base_Dados!$G$3:$G$2000,D7,Base_Dados!$H$3:$H$2000,D8,Base_Dados!$I$3:$I$2000,D9) -> 0
A29: Saúde | B29: =COUNTIFS(Base_Dados!$B$3:$B$2000,">="&D4,Base_Dados!$B$3:$B$2000,"<="&D5,Base_Dados!$F$3:$F$2000,"Saúde",Base_Dados!$G$3:$G$2000,D7,Base_Dados!$H$3:$H$2000,D8,Base_Dados!$I$3:$I$2000,D9) -> 0
A30: Educação | B30: =COUNTIFS(Base_Dados!$B$3:$B$2000,">="&D4,Base_Dados!$B$3:$B$2000,"<="&D5,Base_Dados!$F$3:$F$2000,"Educação",Base_Dados!$G$3:$G$2000,D7,Base_Dados!$H$3:$H$2000,D8,Base_Dados!$I$3:$I$2000,D9) -> 0
A35: Dica: use os filtros para comparar clientes, tipos e instrutores dentro do mês.

Sheet Dashboard_Acumulado
A1: Dashboard T&D — Acumulado (Ano)
A3: Filtros | D3: Critérios (auto) | E3: =COUNTIFS(Base_Dados!$B$3:$B$2000,">="&D4,Base_Dados!$B$3:$B$2000,"<="&D5,Base_Dados!$F$3:$F$2000,D6,Base_Dados!$G$3:$G$2000,D7,Base_Dados!$H$3:$H$2000,D8,Base_Dados!$I$3:$I$2000,D9) -> 15 | G3: =SUMIFS(Base_Dados!$L$3:$L$2000,Base_Dados!$B$3:$B$2000,">="&D4,Base_Dados!$B$3:$B$2000,"<="&D5,Base_Dados!$F$3:$F$2000,D6,Base_Dados!$G$3:$G$2000,D7,Base_Dados!$H$3:$H$2000,D8,Base_Dados!$I$3:$I$2000,D9) -> 858 | I3: =IFERROR(SUMIFS(Base_Dados!$L$3:$L$2000,Base_Dados!$B$3:$B$2000,">="&D4,Base_Dados!$B$3:$B$2000,"<="&D5,Base_Dados!$F$3:$F$2000,D6,Base_Dados!$G$3:$G$2000,D7,Base_Dados!$H$3:$H$2000,D8,Base_Dados!$I$3:$I$2000,D9)/SUMIFS(Base_Dados!$K$3:$K$2000,Base_Dados!$B$3:$B$2000,">="&D4,Base_Dados!$B$3:$B$2000,"<="&D5,Base_Dados!$F$3:$F$2000,D6,Base_Dados!$G$3:$G$2000,D7,Base_Dados!$H$3:$H$2000,D8,Base_Dados!$I$3:$I$2000,D9),0) -> 0.95865922
A4: Data inicial | B4: 46023 | D4: =B4 -> 46023 | E4: Treinamentos | G4: Colab. treinados (presenças) | I4: % presença
A5: Data final | B5: 46387 | D5: =B5 -> 46387 | E5: =IFERROR(AVERAGEIFS(Base_Dados!$O$3:$O$2000,Base_Dados!$B$3:$B$2000,">="&D4,Base_Dados!$B$3:$B$2000,"<="&D5,Base_Dados!$F$3:$F$2000,D6,Base_Dados!$G$3:$G$2000,D7,Base_Dados!$H$3:$H$2000,D8,Base_Dados!$I$3:$I$2000,D9),0) -> 0 | G5: =IFERROR(AVERAGEIFS(Base_Dados!$U$3:$U$2000,Base_Dados!$B$3:$B$2000,">="&D4,Base_Dados!$B$3:$B$2000,"<="&D5,Base_Dados!$F$3:$F$2000,D6,Base_Dados!$G$3:$G$2000,D7,Base_Dados!$H$3:$H$2000,D8,Base_Dados!$I$3:$I$2000,D9,Base_Dados!$P$3:$P$2000,D10),0) -> 0 | I5: =IFERROR(SUMIFS(Base_Dados!$V$3:$V$2000,Base_Dados!$B$3:$B$2000,">="&D4,Base_Dados!$B$3:$B$2000,"<="&D5,Base_Dados!$F$3:$F$2000,D6,Base_Dados!$G$3:$G$2000,D7,Base_Dados!$H$3:$H$2000,D8,Base_Dados!$I$3:$I$2000,D9,Base_Dados!$P$3:$P$2000,D10)/COUNTIFS(Base_Dados!$B$3:$B$2000,">="&D4,Base_Dados!$B$3:$B$2000,"<="&D5,Base_Dados!$F$3:$F$2000,D6,Base_Dados!$G$3:$G$2000,D7,Base_Dados!$H$3:$H$2000,D8,Base_Dados!$I$3:$I$2000,D9),0) -> 0
A6: Cliente | B6: Todos | D6: =IF(B6="Todos","*",B6) -> * | E6: Nota média | G6: Evolução média (indicador) | I6: % turmas c/ impacto +
A7: Tipo de Treinamento | B7: Todos | D7: =IF(B7="Todos","*",B7) -> *
A8: Instrutor | B8: Todos | D8: =IF(B8="Todos","*",B8) -> *
A9: Supervisor | B9: Todos | D9: =IF(B9="Todos","*",B9) -> *
A10: Indicador (para efetividade) | B10: Todos | D10: =IF(B10="Todos","*",B10) -> *
A12: Ano (para gráfico mensal) | B12: 2026
A13: Resumo mensal (Ano selecionado)
A14: Mês | B14: Início | C14: Fim | D14: Treinamentos | E14: Presenças
A15: Janeiro | B15: =DATE($B$12,1,1) -> 46023 | C15: =EOMONTH(B15,0) -> 46053 | D15: =COUNTIFS(Base_Dados!$B$3:$B$2000,">="&B15,Base_Dados!$B$3:$B$2000,"<="&C15,Base_Dados!$F$3:$F$2000,D6,Base_Dados!$G$3:$G$2000,D7,Base_Dados!$H$3:$H$2000,D8,Base_Dados!$I$3:$I$2000,D9) -> 4 | E15: =SUMIFS(Base_Dados!$L$3:$L$2000,Base_Dados!$B$3:$B$2000,">="&B15,Base_Dados!$B$3:$B$2000,"<="&C15,Base_Dados!$F$3:$F$2000,D6,Base_Dados!$G$3:$G$2000,D7,Base_Dados!$H$3:$H$2000,D8,Base_Dados!$I$3:$I$2000,D9) -> 335
A16: Fevereiro | B16: =DATE($B$12,2,1) -> 46054 | C16: =EOMONTH(B16,0) -> 46081 | D16: =COUNTIFS(Base_Dados!$B$3:$B$2000,">="&B16,Base_Dados!$B$3:$B$2000,"<="&C16,Base_Dados!$F$3:$F$2000,D6,Base_Dados!$G$3:$G$2000,D7,Base_Dados!$H$3:$H$2000,D8,Base_Dados!$I$3:$I$2000,D9) -> 10 | E16: =SUMIFS(Base_Dados!$L$3:$L$2000,Base_Dados!$B$3:$B$2000,">="&B16,Base_Dados!$B$3:$B$2000,"<="&C16,Base_Dados!$F$3:$F$2000,D6,Base_Dados!$G$3:$G$2000,D7,Base_Dados!$H$3:$H$2000,D8,Base_Dados!$I$3:$I$2000,D9) -> 513
A17: Março | B17: =DATE($B$12,3,1) -> 46082 | C17: =EOMONTH(B17,0) -> 46112 | D17: =COUNTIFS(Base_Dados!$B$3:$B$2000,">="&B17,Base_Dados!$B$3:$B$2000,"<="&C17,Base_Dados!$F$3:$F$2000,D6,Base_Dados!$G$3:$G$2000,D7,Base_Dados!$H$3:$H$2000,D8,Base_Dados!$I$3:$I$2000,D9) -> 1 | E17: =SUMIFS(Base_Dados!$L$3:$L$2000,Base_Dados!$B$3:$B$2000,">="&B17,Base_Dados!$B$3:$B$2000,"<="&C17,Base_Dados!$F$3:$F$2000,D6,Base_Dados!$G$3:$G$2000,D7,Base_Dados!$H$3:$H$2000,D8,Base_Dados!$I$3:$I$2000,D9) -> 10
A18: Abril | B18: =DATE($B$12,4,1) -> 46113 | C18: =EOMONTH(B18,0) -> 46142 | D18: =COUNTIFS(Base_Dados!$B$3:$B$2000,">="&B18,Base_Dados!$B$3:$B$2000,"<="&C18,Base_Dados!$F$3:$F$2000,D6,Base_Dados!$G$3:$G$2000,D7,Base_Dados!$H$3:$H$2000,D8,Base_Dados!$I$3:$I$2000,D9) -> 0 | E18: =SUMIFS(Base_Dados!$L$3:$L$2000,Base_Dados!$B$3:$B$2000,">="&B18,Base_Dados!$B$3:$B$2000,"<="&C18,Base_Dados!$F$3:$F$2000,D6,Base_Dados!$G$3:$G$2000,D7,Base_Dados!$H$3:$H$2000,D8,Base_Dados!$I$3:$I$2000,D9) -> 0
A19: Maio | B19: =DATE($B$12,5,1) -> 46143 | C19: =EOMONTH(B19,0) -> 46173 | D19: =COUNTIFS(Base_Dados!$B$3:$B$2000,">="&B19,Base_Dados!$B$3:$B$2000,"<="&C19,Base_Dados!$F$3:$F$2000,D6,Base_Dados!$G$3:$G$2000,D7,Base_Dados!$H$3:$H$2000,D8,Base_Dados!$I$3:$I$2000,D9) -> 0 | E19: =SUMIFS(Base_Dados!$L$3:$L$2000,Base_Dados!$B$3:$B$2000,">="&B19,Base_Dados!$B$3:$B$2000,"<="&C19,Base_Dados!$F$3:$F$2000,D6,Base_Dados!$G$3:$G$2000,D7,Base_Dados!$H$3:$H$2000,D8,Base_Dados!$I$3:$I$2000,D9) -> 0
A20: Junho | B20: =DATE($B$12,6,1) -> 46174 | C20: =EOMONTH(B20,0) -> 46203 | D20: =COUNTIFS(Base_Dados!$B$3:$B$2000,">="&B20,Base_Dados!$B$3:$B$2000,"<="&C20,Base_Dados!$F$3:$F$2000,D6,Base_Dados!$G$3:$G$2000,D7,Base_Dados!$H$3:$H$2000,D8,Base_Dados!$I$3:$I$2000,D9) -> 0 | E20: =SUMIFS(Base_Dados!$L$3:$L$2000,Base_Dados!$B$3:$B$2000,">="&B20,Base_Dados!$B$3:$B$2000,"<="&C20,Base_Dados!$F$3:$F$2000,D6,Base_Dados!$G$3:$G$2000,D7,Base_Dados!$H$3:$H$2000,D8,Base_Dados!$I$3:$I$2000,D9) -> 0
A21: Julho | B21: =DATE($B$12,7,1) -> 46204 | C21: =EOMONTH(B21,0) -> 46234 | D21: =COUNTIFS(Base_Dados!$B$3:$B$2000,">="&B21,Base_Dados!$B$3:$B$2000,"<="&C21,Base_Dados!$F$3:$F$2000,D6,Base_Dados!$G$3:$G$2000,D7,Base_Dados!$H$3:$H$2000,D8,Base_Dados!$I$3:$I$2000,D9) -> 0 | E21: =SUMIFS(Base_Dados!$L$3:$L$2000,Base_Dados!$B$3:$B$2000,">="&B21,Base_Dados!$B$3:$B$2000,"<="&C21,Base_Dados!$F$3:$F$2000,D6,Base_Dados!$G$3:$G$2000,D7,Base_Dados!$H$3:$H$2000,D8,Base_Dados!$I$3:$I$2000,D9) -> 0
A22: Agosto | B22: =DATE($B$12,8,1) -> 46235 | C22: =EOMONTH(B22,0) -> 46265 | D22: =COUNTIFS(Base_Dados!$B$3:$B$2000,">="&B22,Base_Dados!$B$3:$B$2000,"<="&C22,Base_Dados!$F$3:$F$2000,D6,Base_Dados!$G$3:$G$2000,D7,Base_Dados!$H$3:$H$2000,D8,Base_Dados!$I$3:$I$2000,D9) -> 0 | E22: =SUMIFS(Base_Dados!$L$3:$L$2000,Base_Dados!$B$3:$B$2000,">="&B22,Base_Dados!$B$3:$B$2000,"<="&C22,Base_Dados!$F$3:$F$2000,D6,Base_Dados!$G$3:$G$2000,D7,Base_Dados!$H$3:$H$2000,D8,Base_Dados!$I$3:$I$2000,D9) -> 0
A23: Setembro | B23: =DATE($B$12,9,1) -> 46266 | C23: =EOMONTH(B23,0) -> 46295 | D23: =COUNTIFS(Base_Dados!$B$3:$B$2000,">="&B23,Base_Dados!$B$3:$B$2000,"<="&C23,Base_Dados!$F$3:$F$2000,D6,Base_Dados!$G$3:$G$2000,D7,Base_Dados!$H$3:$H$2000,D8,Base_Dados!$I$3:$I$2000,D9) -> 0 | E23: =SUMIFS(Base_Dados!$L$3:$L$2000,Base_Dados!$B$3:$B$2000,">="&B23,Base_Dados!$B$3:$B$2000,"<="&C23,Base_Dados!$F$3:$F$2000,D6,Base_Dados!$G$3:$G$2000,D7,Base_Dados!$H$3:$H$2000,D8,Base_Dados!$I$3:$I$2000,D9) -> 0
A24: Outubro | B24: =DATE($B$12,10,1) -> 46296 | C24: =EOMONTH(B24,0) -> 46326 | D24: =COUNTIFS(Base_Dados!$B$3:$B$2000,">="&B24,Base_Dados!$B$3:$B$2000,"<="&C24,Base_Dados!$F$3:$F$2000,D6,Base_Dados!$G$3:$G$2000,D7,Base_Dados!$H$3:$H$2000,D8,Base_Dados!$I$3:$I$2000,D9) -> 0 | E24: =SUMIFS(Base_Dados!$L$3:$L$2000,Base_Dados!$B$3:$B$2000,">="&B24,Base_Dados!$B$3:$B$2000,"<="&C24,Base_Dados!$F$3:$F$2000,D6,Base_Dados!$G$3:$G$2000,D7,Base_Dados!$H$3:$H$2000,D8,Base_Dados!$I$3:$I$2000,D9) -> 0
A25: Novembro | B25: =DATE($B$12,11,1) -> 46327 | C25: =EOMONTH(B25,0) -> 46356 | D25: =COUNTIFS(Base_Dados!$B$3:$B$2000,">="&B25,Base_Dados!$B$3:$B$2000,"<="&C25,Base_Dados!$F$3:$F$2000,D6,Base_Dados!$G$3:$G$2000,D7,Base_Dados!$H$3:$H$2000,D8,Base_Dados!$I$3:$I$2000,D9) -> 0 | E25: =SUMIFS(Base_Dados!$L$3:$L$2000,Base_Dados!$B$3:$B$2000,">="&B25,Base_Dados!$B$3:$B$2000,"<="&C25,Base_Dados!$F$3:$F$2000,D6,Base_Dados!$G$3:$G$2000,D7,Base_Dados!$H$3:$H$2000,D8,Base_Dados!$I$3:$I$2000,D9) -> 0
A26: Dezembro | B26: =DATE($B$12,12,1) -> 46357 | C26: =EOMONTH(B26,0) -> 46387 | D26: =COUNTIFS(Base_Dados!$B$3:$B$2000,">="&B26,Base_Dados!$B$3:$B$2000,"<="&C26,Base_Dados!$F$3:$F$2000,D6,Base_Dados!$G$3:$G$2000,D7,Base_Dados!$H$3:$H$2000,D8,Base_Dados!$I$3:$I$2000,D9) -> 0 | E26: =SUMIFS(Base_Dados!$L$3:$L$2000,Base_Dados!$B$3:$B$2000,">="&B26,Base_Dados!$B$3:$B$2000,"<="&C26,Base_Dados!$F$3:$F$2000,D6,Base_Dados!$G$3:$G$2000,D7,Base_Dados!$H$3:$H$2000,D8,Base_Dados!$I$3:$I$2000,D9) -> 0
A28: Dica: use os filtros acima para ver o acumulado por cliente/tipo/instrutor.

Sheet Efetividade
A1: Efetividade do Treinamento (Impacto)
A3: Filtros | D3: Critérios (auto)
A4: Data inicial | B4: 46054 | D4: =B4 -> 46054
A5: Data final | B5: 46081 | D5: =B5 -> 46081
A6: Cliente | B6: Todos | D6: =IF(B6="Todos","*",B6) -> *
A7: Tipo de Treinamento | B7: Todos | D7: =IF(B7="Todos","*",B7) -> *
A8: Instrutor | B8: Todos | D8: =IF(B8="Todos","*",B8) -> *
A9: Supervisor | B9: Todos | D9: =IF(B9="Todos","*",B9) -> *
A10: Indicador (para efetividade) | B10: Todos | D10: =IF(B10="Todos","*",B10) -> *
A12: Média de evolução (%) por tipo de treinamento (filtros aplicados acima)
A13: Tipo de Treinamento | B13: Treinamentos | C13: % impacto + | D13: Evolução média | E13: Nota média
A14: Inicial | B14: =COUNTIFS(Base_Dados!$B$3:$B$2000,">="&D4,Base_Dados!$B$3:$B$2000,"<="&D5,Base_Dados!$F$3:$F$2000,D6,Base_Dados!$G$3:$G$2000,"Inicial",Base_Dados!$H$3:$H$2000,D8,Base_Dados!$I$3:$I$2000,D9,Base_Dados!$P$3:$P$2000,D10) -> 0 | C14: =IFERROR(SUMIFS(Base_Dados!$V$3:$V$2000,Base_Dados!$B$3:$B$2000,">="&D4,Base_Dados!$B$3:$B$2000,"<="&D5,Base_Dados!$F$3:$F$2000,D6,Base_Dados!$G$3:$G$2000,"Inicial",Base_Dados!$H$3:$H$2000,D8,Base_Dados!$I$3:$I$2000,D9,Base_Dados!$P$3:$P$2000,D10)/COUNTIFS(Base_Dados!$B$3:$B$2000,">="&D4,Base_Dados!$B$3:$B$2000,"<="&D5,Base_Dados!$F$3:$F$2000,D6,Base_Dados!$G$3:$G$2000,"Inicial",Base_Dados!$H$3:$H$2000,D8,Base_Dados!$I$3:$I$2000,D9,Base_Dados!$P$3:$P$2000,D10),0) -> 0 | D14: =IFERROR(AVERAGEIFS(Base_Dados!$U$3:$U$2000,Base_Dados!$B$3:$B$2000,">="&D4,Base_Dados!$B$3:$B$2000,"<="&D5,Base_Dados!$F$3:$F$2000,D6,Base_Dados!$G$3:$G$2000,"Inicial",Base_Dados!$H$3:$H$2000,D8,Base_Dados!$I$3:$I$2000,D9,Base_Dados!$P$3:$P$2000,D10),0) -> 0 | E14: =IFERROR(AVERAGEIFS(Base_Dados!$O$3:$O$2000,Base_Dados!$B$3:$B$2000,">="&D4,Base_Dados!$B$3:$B$2000,"<="&D5,Base_Dados!$F$3:$F$2000,D6,Base_Dados!$G$3:$G$2000,"Inicial",Base_Dados!$H$3:$H$2000,D8,Base_Dados!$I$3:$I$2000,D9),0) -> 0
A15: Reciclagem | B15: =COUNTIFS(Base_Dados!$B$3:$B$2000,">="&D4,Base_Dados!$B$3:$B$2000,"<="&D5,Base_Dados!$F$3:$F$2000,D6,Base_Dados!$G$3:$G$2000,"Reciclagem",Base_Dados!$H$3:$H$2000,D8,Base_Dados!$I$3:$I$2000,D9,Base_Dados!$P$3:$P$2000,D10) -> 0 | C15: =IFERROR(SUMIFS(Base_Dados!$V$3:$V$2000,Base_Dados!$B$3:$B$2000,">="&D4,Base_Dados!$B$3:$B$2000,"<="&D5,Base_Dados!$F$3:$F$2000,D6,Base_Dados!$G$3:$G$2000,"Reciclagem",Base_Dados!$H$3:$H$2000,D8,Base_Dados!$I$3:$I$2000,D9,Base_Dados!$P$3:$P$2000,D10)/COUNTIFS(Base_Dados!$B$3:$B$2000,">="&D4,Base_Dados!$B$3:$B$2000,"<="&D5,Base_Dados!$F$3:$F$2000,D6,Base_Dados!$G$3:$G$2000,"Reciclagem",Base_Dados!$H$3:$H$2000,D8,Base_Dados!$I$3:$I$2000,D9,Base_Dados!$P$3:$P$2000,D10),0) -> 0 | D15: =IFERROR(AVERAGEIFS(Base_Dados!$U$3:$U$2000,Base_Dados!$B$3:$B$2000,">="&D4,Base_Dados!$B$3:$B$2000,"<="&D5,Base_Dados!$F$3:$F$2000,D6,Base_Dados!$G$3:$G$2000,"Reciclagem",Base_Dados!$H$3:$H$2000,D8,Base_Dados!$I$3:$I$2000,D9,Base_Dados!$P$3:$P$2000,D10),0) -> 0 | E15: =IFERROR(AVERAGEIFS(Base_Dados!$O$3:$O$2000,Base_Dados!$B$3:$B$2000,">="&D4,Base_Dados!$B$3:$B$2000,"<="&D5,Base_Dados!$F$3:$F$2000,D6,Base_Dados!$G$3:$G$2000,"Reciclagem",Base_Dados!$H$3:$H$2000,D8,Base_Dados!$I$3:$I$2000,D9),0) -> 0
A16: Atualização | B16: =COUNTIFS(Base_Dados!$B$3:$B$2000,">="&D4,Base_Dados!$B$3:$B$2000,"<="&D5,Base_Dados!$F$3:$F$2000,D6,Base_Dados!$G$3:$G$2000,"Atualização",Base_Dados!$H$3:$H$2000,D8,Base_Dados!$I$3:$I$2000,D9,Base_Dados!$P$3:$P$2000,D10) -> 0 | C16: =IFERROR(SUMIFS(Base_Dados!$V$3:$V$2000,Base_Dados!$B$3:$B$2000,">="&D4,Base_Dados!$B$3:$B$2000,"<="&D5,Base_Dados!$F$3:$F$2000,D6,Base_Dados!$G$3:$G$2000,"Atualização",Base_Dados!$H$3:$H$2000,D8,Base_Dados!$I$3:$I$2000,D9,Base_Dados!$P$3:$P$2000,D10)/COUNTIFS(Base_Dados!$B$3:$B$2000,">="&D4,Base_Dados!$B$3:$B$2000,"<="&D5,Base_Dados!$F$3:$F$2000,D6,Base_Dados!$G$3:$G$2000,"Atualização",Base_Dados!$H$3:$H$2000,D8,Base_Dados!$I$3:$I$2000,D9,Base_Dados!$P$3:$P$2000,D10),0) -> 0 | D16: =IFERROR(AVERAGEIFS(Base_Dados!$U$3:$U$2000,Base_Dados!$B$3:$B$2000,">="&D4,Base_Dados!$B$3:$B$2000,"<="&D5,Base_Dados!$F$3:$F$2000,D6,Base_Dados!$G$3:$G$2000,"Atualização",Base_Dados!$H$3:$H$2000,D8,Base_Dados!$I$3:$I$2000,D9,Base_Dados!$P$3:$P$2000,D10),0) -> 0 | E16: =IFERROR(AVERAGEIFS(Base_Dados!$O$3:$O$2000,Base_Dados!$B$3:$B$2000,">="&D4,Base_Dados!$B$3:$B$2000,"<="&D5,Base_Dados!$F$3:$F$2000,D6,Base_Dados!$G$3:$G$2000,"Atualização",Base_Dados!$H$3:$H$2000,D8,Base_Dados!$I$3:$I$2000,D9),0) -> 0
A17: Produto | B17: =COUNTIFS(Base_Dados!$B$3:$B$2000,">="&D4,Base_Dados!$B$3:$B$2000,"<="&D5,Base_Dados!$F$3:$F$2000,D6,Base_Dados!$G$3:$G$2000,"Produto",Base_Dados!$H$3:$H$2000,D8,Base_Dados!$I$3:$I$2000,D9,Base_Dados!$P$3:$P$2000,D10) -> 0 | C17: =IFERROR(SUMIFS(Base_Dados!$V$3:$V$2000,Base_Dados!$B$3:$B$2000,">="&D4,Base_Dados!$B$3:$B$2000,"<="&D5,Base_Dados!$F$3:$F$2000,D6,Base_Dados!$G$3:$G$2000,"Produto",Base_Dados!$H$3:$H$2000,D8,Base_Dados!$I$3:$I$2000,D9,Base_Dados!$P$3:$P$2000,D10)/COUNTIFS(Base_Dados!$B$3:$B$2000,">="&D4,Base_Dados!$B$3:$B$2000,"<="&D5,Base_Dados!$F$3:$F$2000,D6,Base_Dados!$G$3:$G$2000,"Produto",Base_Dados!$H$3:$H$2000,D8,Base_Dados!$I$3:$I$2000,D9,Base_Dados!$P$3:$P$2000,D10),0) -> 0 | D17: =IFERROR(AVERAGEIFS(Base_Dados!$U$3:$U$2000,Base_Dados!$B$3:$B$2000,">="&D4,Base_Dados!$B$3:$B$2000,"<="&D5,Base_Dados!$F$3:$F$2000,D6,Base_Dados!$G$3:$G$2000,"Produto",Base_Dados!$H$3:$H$2000,D8,Base_Dados!$I$3:$I$2000,D9,Base_Dados!$P$3:$P$2000,D10),0) -> 0 | E17: =IFERROR(AVERAGEIFS(Base_Dados!$O$3:$O$2000,Base_Dados!$B$3:$B$2000,">="&D4,Base_Dados!$B$3:$B$2000,"<="&D5,Base_Dados!$F$3:$F$2000,D6,Base_Dados!$G$3:$G$2000,"Produto",Base_Dados!$H$3:$H$2000,D8,Base_Dados!$I$3:$I$2000,D9),0) -> 0
A18: Qualidade | B18: =COUNTIFS(Base_Dados!$B$3:$B$2000,">="&D4,Base_Dados!$B$3:$B$2000,"<="&D5,Base_Dados!$F$3:$F$2000,D6,Base_Dados!$G$3:$G$2000,"Qualidade",Base_Dados!$H$3:$H$2000,D8,Base_Dados!$I$3:$I$2000,D9,Base_Dados!$P$3:$P$2000,D10) -> 0 | C18: =IFERROR(SUMIFS(Base_Dados!$V$3:$V$2000,Base_Dados!$B$3:$B$2000,">="&D4,Base_Dados!$B$3:$B$2000,"<="&D5,Base_Dados!$F$3:$F$2000,D6,Base_Dados!$G$3:$G$2000,"Qualidade",Base_Dados!$H$3:$H$2000,D8,Base_Dados!$I$3:$I$2000,D9,Base_Dados!$P$3:$P$2000,D10)/COUNTIFS(Base_Dados!$B$3:$B$2000,">="&D4,Base_Dados!$B$3:$B$2000,"<="&D5,Base_Dados!$F$3:$F$2000,D6,Base_Dados!$G$3:$G$2000,"Qualidade",Base_Dados!$H$3:$H$2000,D8,Base_Dados!$I$3:$I$2000,D9,Base_Dados!$P$3:$P$2000,D10),0) -> 0 | D18: =IFERROR(AVERAGEIFS(Base_Dados!$U$3:$U$2000,Base_Dados!$B$3:$B$2000,">="&D4,Base_Dados!$B$3:$B$2000,"<="&D5,Base_Dados!$F$3:$F$2000,D6,Base_Dados!$G$3:$G$2000,"Qualidade",Base_Dados!$H$3:$H$2000,D8,Base_Dados!$I$3:$I$2000,D9,Base_Dados!$P$3:$P$2000,D10),0) -> 0 | E18: =IFERROR(AVERAGEIFS(Base_Dados!$O$3:$O$2000,Base_Dados!$B$3:$B$2000,">="&D4,Base_Dados!$B$3:$B$2000,"<="&D5,Base_Dados!$F$3:$F$2000,D6,Base_Dados!$G$3:$G$2000,"Qualidade",Base_Dados!$H$3:$H$2000,D8,Base_Dados!$I$3:$I$2000,D9),0) -> 0
A19: Comportamental | B19: =COUNTIFS(Base_Dados!$B$3:$B$2000,">="&D4,Base_Dados!$B$3:$B$2000,"<="&D5,Base_Dados!$F$3:$F$2000,D6,Base_Dados!$G$3:$G$2000,"Comportamental",Base_Dados!$H$3:$H$2000,D8,Base_Dados!$I$3:$I$2000,D9,Base_Dados!$P$3:$P$2000,D10) -> 0 | C19: =IFERROR(SUMIFS(Base_Dados!$V$3:$V$2000,Base_Dados!$B$3:$B$2000,">="&D4,Base_Dados!$B$3:$B$2000,"<="&D5,Base_Dados!$F$3:$F$2000,D6,Base_Dados!$G$3:$G$2000,"Comportamental",Base_Dados!$H$3:$H$2000,D8,Base_Dados!$I$3:$I$2000,D9,Base_Dados!$P$3:$P$2000,D10)/COUNTIFS(Base_Dados!$B$3:$B$2000,">="&D4,Base_Dados!$B$3:$B$2000,"<="&D5,Base_Dados!$F$3:$F$2000,D6,Base_Dados!$G$3:$G$2000,"Comportamental",Base_Dados!$H$3:$H$2000,D8,Base_Dados!$I$3:$I$2000,D9,Base_Dados!$P$3:$P$2000,D10),0) -> 0 | D19: =IFERROR(AVERAGEIFS(Base_Dados!$U$3:$U$2000,Base_Dados!$B$3:$B$2000,">="&D4,Base_Dados!$B$3:$B$2000,"<="&D5,Base_Dados!$F$3:$F$2000,D6,Base_Dados!$G$3:$G$2000,"Comportamental",Base_Dados!$H$3:$H$2000,D8,Base_Dados!$I$3:$I$2000,D9,Base_Dados!$P$3:$P$2000,D10),0) -> 0 | E19: =IFERROR(AVERAGEIFS(Base_Dados!$O$3:$O$2000,Base_Dados!$B$3:$B$2000,">="&D4,Base_Dados!$B$3:$B$2000,"<="&D5,Base_Dados!$F$3:$F$2000,D6,Base_Dados!$G$3:$G$2000,"Comportamental",Base_Dados!$H$3:$H$2000,D8,Base_Dados!$I$3:$I$2000,D9),0) -> 0
A20: Processos | B20: =COUNTIFS(Base_Dados!$B$3:$B$2000,">="&D4,Base_Dados!$B$3:$B$2000,"<="&D5,Base_Dados!$F$3:$F$2000,D6,Base_Dados!$G$3:$G$2000,"Processos",Base_Dados!$H$3:$H$2000,D8,Base_Dados!$I$3:$I$2000,D9,Base_Dados!$P$3:$P$2000,D10) -> 0 | C20: =IFERROR(SUMIFS(Base_Dados!$V$3:$V$2000,Base_Dados!$B$3:$B$2000,">="&D4,Base_Dados!$B$3:$B$2000,"<="&D5,Base_Dados!$F$3:$F$2000,D6,Base_Dados!$G$3:$G$2000,"Processos",Base_Dados!$H$3:$H$2000,D8,Base_Dados!$I$3:$I$2000,D9,Base_Dados!$P$3:$P$2000,D10)/COUNTIFS(Base_Dados!$B$3:$B$2000,">="&D4,Base_Dados!$B$3:$B$2000,"<="&D5,Base_Dados!$F$3:$F$2000,D6,Base_Dados!$G$3:$G$2000,"Processos",Base_Dados!$H$3:$H$2000,D8,Base_Dados!$I$3:$I$2000,D9,Base_Dados!$P$3:$P$2000,D10),0) -> 0 | D20: =IFERROR(AVERAGEIFS(Base_Dados!$U$3:$U$2000,Base_Dados!$B$3:$B$2000,">="&D4,Base_Dados!$B$3:$B$2000,"<="&D5,Base_Dados!$F$3:$F$2000,D6,Base_Dados!$G$3:$G$2000,"Processos",Base_Dados!$H$3:$H$2000,D8,Base_Dados!$I$3:$I$2000,D9,Base_Dados!$P$3:$P$2000,D10),0) -> 0 | E20: =IFERROR(AVERAGEIFS(Base_Dados!$O$3:$O$2000,Base_Dados!$B$3:$B$2000,">="&D4,Base_Dados!$B$3:$B$2000,"<="&D5,Base_Dados!$F$3:$F$2000,D6,Base_Dados!$G$3:$G$2000,"Processos",Base_Dados!$H$3:$H$2000,D8,Base_Dados!$I$3:$I$2000,D9),0) -> 0
A21: Tecnologia | B21: =COUNTIFS(Base_Dados!$B$3:$B$2000,">="&D4,Base_Dados!$B$3:$B$2000,"<="&D5,Base_Dados!$F$3:$F$2000,D6,Base_Dados!$G$3:$G$2000,"Tecnologia",Base_Dados!$H$3:$H$2000,D8,Base_Dados!$I$3:$I$2000,D9,Base_Dados!$P$3:$P$2000,D10) -> 0 | C21: =IFERROR(SUMIFS(Base_Dados!$V$3:$V$2000,Base_Dados!$B$3:$B$2000,">="&D4,Base_Dados!$B$3:$B$2000,"<="&D5,Base_Dados!$F$3:$F$2000,D6,Base_Dados!$G$3:$G$2000,"Tecnologia",Base_Dados!$H$3:$H$2000,D8,Base_Dados!$I$3:$I$2000,D9,Base_Dados!$P$3:$P$2000,D10)/COUNTIFS(Base_Dados!$B$3:$B$2000,">="&D4,Base_Dados!$B$3:$B$2000,"<="&D5,Base_Dados!$F$3:$F$2000,D6,Base_Dados!$G$3:$G$2000,"Tecnologia",Base_Dados!$H$3:$H$2000,D8,Base_Dados!$I$3:$I$2000,D9,Base_Dados!$P$3:$P$2000,D10),0) -> 0 | D21: =IFERROR(AVERAGEIFS(Base_Dados!$U$3:$U$2000,Base_Dados!$B$3:$B$2000,">="&D4,Base_Dados!$B$3:$B$2000,"<="&D5,Base_Dados!$F$3:$F$2000,D6,Base_Dados!$G$3:$G$2000,"Tecnologia",Base_Dados!$H$3:$H$2000,D8,Base_Dados!$I$3:$I$2000,D9,Base_Dados!$P$3:$P$2000,D10),0) -> 0 | E21: =IFERROR(AVERAGEIFS(Base_Dados!$O$3:$O$2000,Base_Dados!$B$3:$B$2000,">="&D4,Base_Dados!$B$3:$B$2000,"<="&D5,Base_Dados!$F$3:$F$2000,D6,Base_Dados!$G$3:$G$2000,"Tecnologia",Base_Dados!$H$3:$H$2000,D8,Base_Dados!$I$3:$I$2000,D9),0) -> 0
A24: Evolução média por indicador
A25: Indicador | B25: Evolução média
A26: Qualidade | B26: =IFERROR(AVERAGEIFS(Base_Dados!$U$3:$U$2000,Base_Dados!$B$3:$B$2000,">="&D4,Base_Dados!$B$3:$B$2000,"<="&D5,Base_Dados!$F$3:$F$2000,D6,Base_Dados!$G$3:$G$2000,D7,Base_Dados!$H$3:$H$2000,D8,Base_Dados!$I$3:$I$2000,D9,Base_Dados!$P$3:$P$2000,"Qualidade"),0) -> 0
A27: TMA | B27: =IFERROR(AVERAGEIFS(Base_Dados!$U$3:$U$2000,Base_Dados!$B$3:$B$2000,">="&D4,Base_Dados!$B$3:$B$2000,"<="&D5,Base_Dados!$F$3:$F$2000,D6,Base_Dados!$G$3:$G$2000,D7,Base_Dados!$H$3:$H$2000,D8,Base_Dados!$I$3:$I$2000,D9,Base_Dados!$P$3:$P$2000,"TMA"),0) -> 0
A28: Conversao | B28: =IFERROR(AVERAGEIFS(Base_Dados!$U$3:$U$2000,Base_Dados!$B$3:$B$2000,">="&D4,Base_Dados!$B$3:$B$2000,"<="&D5,Base_Dados!$F$3:$F$2000,D6,Base_Dados!$G$3:$G$2000,D7,Base_Dados!$H$3:$H$2000,D8,Base_Dados!$I$3:$I$2000,D9,Base_Dados!$P$3:$P$2000,"Conversao"),0) -> 0
A29: NPS | B29: =IFERROR(AVERAGEIFS(Base_Dados!$U$3:$U$2000,Base_Dados!$B$3:$B$2000,">="&D4,Base_Dados!$B$3:$B$2000,"<="&D5,Base_Dados!$F$3:$F$2000,D6,Base_Dados!$G$3:$G$2000,D7,Base_Dados!$H$3:$H$2000,D8,Base_Dados!$I$3:$I$2000,D9,Base_Dados!$P$3:$P$2000,"NPS"),0) -> 0
A32: Observação: “Evolução %” é calculada por (Depois - Antes) / Antes na Base_Dados.

Sheet Instrutores
A1: Performance — Instrutores
A3: Filtros | D3: Critérios (auto)
A4: Data inicial | B4: 46054 | D4: =B4 -> 46054
A5: Data final | B5: 46081 | D5: =B5 -> 46081
A6: Cliente | B6: Todos | D6: =IF(B6="Todos","*",B6) -> *
A7: Tipo de Treinamento | B7: Todos | D7: =IF(B7="Todos","*",B7) -> *
A8: Instrutor | B8: Todos | D8: =IF(B8="Todos","*",B8) -> *
A9: Supervisor | B9: Todos | D9: =IF(B9="Todos","*",B9) -> *
A10: Indicador (para efetividade) | B10: Todos | D10: =IF(B10="Todos","*",B10) -> *
A12: Indicadores por instrutor (filtros aplicados acima)
A13: Instrutor | B13: Treinamentos | C13: Presenças | D13: % presença | E13: Nota média | F13: Evolução média
A14: Evelin Rocha | B14: =COUNTIFS(Base_Dados!$B$3:$B$2000,">="&$D$4,Base_Dados!$B$3:$B$2000,"<="&$D$5,Base_Dados!$F$3:$F$2000,$D$6,Base_Dados!$G$3:$G$2000,D7,Base_Dados!$H$3:$H$2000,A14,Base_Dados!$I$3:$I$2000,$D$9) -> 1 | C14: =SUMIFS(Base_Dados!$L$3:$L$2000,Base_Dados!$B$3:$B$2000,">="&$D$4,Base_Dados!$B$3:$B$2000,"<="&$D$5,Base_Dados!$F$3:$F$2000,$D$6,Base_Dados!$G$3:$G$2000,$D$7,Base_Dados!$H$3:$H$2000,A14,Base_Dados!$I$3:$I$2000,$D$9) -> 17 | D14: =IFERROR(SUMIFS(Base_Dados!$L$3:$L$2000,Base_Dados!$B$3:$B$2000,">="&$D$4,Base_Dados!$B$3:$B$2000,"<="&$D$5,Base_Dados!$F$3:$F$2000,$D$6,Base_Dados!$G$3:$G$2000,$D$7,Base_Dados!$H$3:$H$2000,A14,Base_Dados!$I$3:$I$2000,$D$9)/SUMIFS(Base_Dados!$K$3:$K$2000,Base_Dados!$B$3:$B$2000,">="&$D$4,Base_Dados!$B$3:$B$2000,"<="&$D$5,Base_Dados!$F$3:$F$2000,$D$6,Base_Dados!$G$3:$G$2000,$D$7,Base_Dados!$H$3:$H$2000,A14,Base_Dados!$I$3:$I$2000,$D$9),0) -> 1 | E14: =IFERROR(AVERAGEIFS(Base_Dados!$O$3:$O$2000,Base_Dados!$B$3:$B$2000,">="&$D$4,Base_Dados!$B$3:$B$2000,"<="&$D$5,Base_Dados!$F$3:$F$2000,$D$6,Base_Dados!$G$3:$G$2000,$D$7,Base_Dados!$H$3:$H$2000,A14,Base_Dados!$I$3:$I$2000,$D$9),0) -> 0 | F14: =IFERROR(AVERAGEIFS(Base_Dados!$U$3:$U$2000,Base_Dados!$B$3:$B$2000,">="&$D$4,Base_Dados!$B$3:$B$2000,"<="&$D$5,Base_Dados!$F$3:$F$2000,$D$6,Base_Dados!$G$3:$G$2000,$D$7,Base_Dados!$H$3:$H$2000,A14,Base_Dados!$I$3:$I$2000,$D$9,Base_Dados!$P$3:$P$2000,$D$10),0) -> 0
A15: Laiane Santos | B15: =COUNTIFS(Base_Dados!$B$3:$B$2000,">="&$D$4,Base_Dados!$B$3:$B$2000,"<="&$D$5,Base_Dados!$F$3:$F$2000,$D$6,Base_Dados!$G$3:$G$2000,D8,Base_Dados!$H$3:$H$2000,A15,Base_Dados!$I$3:$I$2000,$D$9) -> 1 | C15: =SUMIFS(Base_Dados!$L$3:$L$2000,Base_Dados!$B$3:$B$2000,">="&$D$4,Base_Dados!$B$3:$B$2000,"<="&$D$5,Base_Dados!$F$3:$F$2000,$D$6,Base_Dados!$G$3:$G$2000,$D$7,Base_Dados!$H$3:$H$2000,A15,Base_Dados!$I$3:$I$2000,$D$9) -> 145 | D15: =IFERROR(SUMIFS(Base_Dados!$L$3:$L$2000,Base_Dados!$B$3:$B$2000,">="&$D$4,Base_Dados!$B$3:$B$2000,"<="&$D$5,Base_Dados!$F$3:$F$2000,$D$6,Base_Dados!$G$3:$G$2000,$D$7,Base_Dados!$H$3:$H$2000,A15,Base_Dados!$I$3:$I$2000,$D$9)/SUMIFS(Base_Dados!$K$3:$K$2000,Base_Dados!$B$3:$B$2000,">="&$D$4,Base_Dados!$B$3:$B$2000,"<="&$D$5,Base_Dados!$F$3:$F$2000,$D$6,Base_Dados!$G$3:$G$2000,$D$7,Base_Dados!$H$3:$H$2000,A15,Base_Dados!$I$3:$I$2000,$D$9),0) -> 0.81005587 | E15: =IFERROR(AVERAGEIFS(Base_Dados!$O$3:$O$2000,Base_Dados!$B$3:$B$2000,">="&$D$4,Base_Dados!$B$3:$B$2000,"<="&$D$5,Base_Dados!$F$3:$F$2000,$D$6,Base_Dados!$G$3:$G$2000,$D$7,Base_Dados!$H$3:$H$2000,A15,Base_Dados!$I$3:$I$2000,$D$9),0) -> 0 | F15: =IFERROR(AVERAGEIFS(Base_Dados!$U$3:$U$2000,Base_Dados!$B$3:$B$2000,">="&$D$4,Base_Dados!$B$3:$B$2000,"<="&$D$5,Base_Dados!$F$3:$F$2000,$D$6,Base_Dados!$G$3:$G$2000,$D$7,Base_Dados!$H$3:$H$2000,A15,Base_Dados!$I$3:$I$2000,$D$9,Base_Dados!$P$3:$P$2000,$D$10),0) -> 0
A16: Leticia Ramos | B16: =COUNTIFS(Base_Dados!$B$3:$B$2000,">="&$D$4,Base_Dados!$B$3:$B$2000,"<="&$D$5,Base_Dados!$F$3:$F$2000,$D$6,Base_Dados!$G$3:$G$2000,D9,Base_Dados!$H$3:$H$2000,A16,Base_Dados!$I$3:$I$2000,$D$9) -> 1 | C16: =SUMIFS(Base_Dados!$L$3:$L$2000,Base_Dados!$B$3:$B$2000,">="&$D$4,Base_Dados!$B$3:$B$2000,"<="&$D$5,Base_Dados!$F$3:$F$2000,$D$6,Base_Dados!$G$3:$G$2000,$D$7,Base_Dados!$H$3:$H$2000,A16,Base_Dados!$I$3:$I$2000,$D$9) -> 9 | D16: =IFERROR(SUMIFS(Base_Dados!$L$3:$L$2000,Base_Dados!$B$3:$B$2000,">="&$D$4,Base_Dados!$B$3:$B$2000,"<="&$D$5,Base_Dados!$F$3:$F$2000,$D$6,Base_Dados!$G$3:$G$2000,$D$7,Base_Dados!$H$3:$H$2000,A16,Base_Dados!$I$3:$I$2000,$D$9)/SUMIFS(Base_Dados!$K$3:$K$2000,Base_Dados!$B$3:$B$2000,">="&$D$4,Base_Dados!$B$3:$B$2000,"<="&$D$5,Base_Dados!$F$3:$F$2000,$D$6,Base_Dados!$G$3:$G$2000,$D$7,Base_Dados!$H$3:$H$2000,A16,Base_Dados!$I$3:$I$2000,$D$9),0) -> 1 | E16: =IFERROR(AVERAGEIFS(Base_Dados!$O$3:$O$2000,Base_Dados!$B$3:$B$2000,">="&$D$4,Base_Dados!$B$3:$B$2000,"<="&$D$5,Base_Dados!$F$3:$F$2000,$D$6,Base_Dados!$G$3:$G$2000,$D$7,Base_Dados!$H$3:$H$2000,A16,Base_Dados!$I$3:$I$2000,$D$9),0) -> 0 | F16: =IFERROR(AVERAGEIFS(Base_Dados!$U$3:$U$2000,Base_Dados!$B$3:$B$2000,">="&$D$4,Base_Dados!$B$3:$B$2000,"<="&$D$5,Base_Dados!$F$3:$F$2000,$D$6,Base_Dados!$G$3:$G$2000,$D$7,Base_Dados!$H$3:$H$2000,A16,Base_Dados!$I$3:$I$2000,$D$9,Base_Dados!$P$3:$P$2000,$D$10),0) -> 0
A17: Hiago Amor | B17: =COUNTIFS(Base_Dados!$B$3:$B$2000,">="&$D$4,Base_Dados!$B$3:$B$2000,"<="&$D$5,Base_Dados!$F$3:$F$2000,$D$6,Base_Dados!$G$3:$G$2000,D10,Base_Dados!$H$3:$H$2000,A17,Base_Dados!$I$3:$I$2000,$D$9) -> 1 | C17: =SUMIFS(Base_Dados!$L$3:$L$2000,Base_Dados!$B$3:$B$2000,">="&$D$4,Base_Dados!$B$3:$B$2000,"<="&$D$5,Base_Dados!$F$3:$F$2000,$D$6,Base_Dados!$G$3:$G$2000,$D$7,Base_Dados!$H$3:$H$2000,A17,Base_Dados!$I$3:$I$2000,$D$9) -> 29 | D17: =IFERROR(SUMIFS(Base_Dados!$L$3:$L$2000,Base_Dados!$B$3:$B$2000,">="&$D$4,Base_Dados!$B$3:$B$2000,"<="&$D$5,Base_Dados!$F$3:$F$2000,$D$6,Base_Dados!$G$3:$G$2000,$D$7,Base_Dados!$H$3:$H$2000,A17,Base_Dados!$I$3:$I$2000,$D$9)/SUMIFS(Base_Dados!$K$3:$K$2000,Base_Dados!$B$3:$B$2000,">="&$D$4,Base_Dados!$B$3:$B$2000,"<="&$D$5,Base_Dados!$F$3:$F$2000,$D$6,Base_Dados!$G$3:$G$2000,$D$7,Base_Dados!$H$3:$H$2000,A17,Base_Dados!$I$3:$I$2000,$D$9),0) -> 0.90625 | E17: =IFERROR(AVERAGEIFS(Base_Dados!$O$3:$O$2000,Base_Dados!$B$3:$B$2000,">="&$D$4,Base_Dados!$B$3:$B$2000,"<="&$D$5,Base_Dados!$F$3:$F$2000,$D$6,Base_Dados!$G$3:$G$2000,$D$7,Base_Dados!$H$3:$H$2000,A17,Base_Dados!$I$3:$I$2000,$D$9),0) -> 0 | F17: =IFERROR(AVERAGEIFS(Base_Dados!$U$3:$U$2000,Base_Dados!$B$3:$B$2000,">="&$D$4,Base_Dados!$B$3:$B$2000,"<="&$D$5,Base_Dados!$F$3:$F$2000,$D$6,Base_Dados!$G$3:$G$2000,$D$7,Base_Dados!$H$3:$H$2000,A17,Base_Dados!$I$3:$I$2000,$D$9,Base_Dados!$P$3:$P$2000,$D$10),0) -> 0
A18: Maricelia Santos | B18: =COUNTIFS(Base_Dados!$B$3:$B$2000,">="&$D$4,Base_Dados!$B$3:$B$2000,"<="&$D$5,Base_Dados!$F$3:$F$2000,$D$6,Base_Dados!$G$3:$G$2000,D11,Base_Dados!$H$3:$H$2000,A18,Base_Dados!$I$3:$I$2000,$D$9) -> 0 | C18: =SUMIFS(Base_Dados!$L$3:$L$2000,Base_Dados!$B$3:$B$2000,">="&$D$4,Base_Dados!$B$3:$B$2000,"<="&$D$5,Base_Dados!$F$3:$F$2000,$D$6,Base_Dados!$G$3:$G$2000,$D$7,Base_Dados!$H$3:$H$2000,A18,Base_Dados!$I$3:$I$2000,$D$9) -> 0 | D18: =IFERROR(SUMIFS(Base_Dados!$L$3:$L$2000,Base_Dados!$B$3:$B$2000,">="&$D$4,Base_Dados!$B$3:$B$2000,"<="&$D$5,Base_Dados!$F$3:$F$2000,$D$6,Base_Dados!$G$3:$G$2000,$D$7,Base_Dados!$H$3:$H$2000,A18,Base_Dados!$I$3:$I$2000,$D$9)/SUMIFS(Base_Dados!$K$3:$K$2000,Base_Dados!$B$3:$B$2000,">="&$D$4,Base_Dados!$B$3:$B$2000,"<="&$D$5,Base_Dados!$F$3:$F$2000,$D$6,Base_Dados!$G$3:$G$2000,$D$7,Base_Dados!$H$3:$H$2000,A18,Base_Dados!$I$3:$I$2000,$D$9),0) -> 0 | E18: =IFERROR(AVERAGEIFS(Base_Dados!$O$3:$O$2000,Base_Dados!$B$3:$B$2000,">="&$D$4,Base_Dados!$B$3:$B$2000,"<="&$D$5,Base_Dados!$F$3:$F$2000,$D$6,Base_Dados!$G$3:$G$2000,$D$7,Base_Dados!$H$3:$H$2000,A18,Base_Dados!$I$3:$I$2000,$D$9),0) -> 0 | F18: =IFERROR(AVERAGEIFS(Base_Dados!$U$3:$U$2000,Base_Dados!$B$3:$B$2000,">="&$D$4,Base_Dados!$B$3:$B$2000,"<="&$D$5,Base_Dados!$F$3:$F$2000,$D$6,Base_Dados!$G$3:$G$2000,$D$7,Base_Dados!$H$3:$H$2000,A18,Base_Dados!$I$3:$I$2000,$D$9,Base_Dados!$P$3:$P$2000,$D$10),0) -> 0
A19: Diogo Silva | B19: =COUNTIFS(Base_Dados!$B$3:$B$2000,">="&$D$4,Base_Dados!$B$3:$B$2000,"<="&$D$5,Base_Dados!$F$3:$F$2000,$D$6,Base_Dados!$G$3:$G$2000,D12,Base_Dados!$H$3:$H$2000,A19,Base_Dados!$I$3:$I$2000,$D$9) -> 0 | C19: =SUMIFS(Base_Dados!$L$3:$L$2000,Base_Dados!$B$3:$B$2000,">="&$D$4,Base_Dados!$B$3:$B$2000,"<="&$D$5,Base_Dados!$F$3:$F$2000,$D$6,Base_Dados!$G$3:$G$2000,$D$7,Base_Dados!$H$3:$H$2000,A19,Base_Dados!$I$3:$I$2000,$D$9) -> 6 | D19: =IFERROR(SUMIFS(Base_Dados!$L$3:$L$2000,Base_Dados!$B$3:$B$2000,">="&$D$4,Base_Dados!$B$3:$B$2000,"<="&$D$5,Base_Dados!$F$3:$F$2000,$D$6,Base_Dados!$G$3:$G$2000,$D$7,Base_Dados!$H$3:$H$2000,A19,Base_Dados!$I$3:$I$2000,$D$9)/SUMIFS(Base_Dados!$K$3:$K$2000,Base_Dados!$B$3:$B$2000,">="&$D$4,Base_Dados!$B$3:$B$2000,"<="&$D$5,Base_Dados!$F$3:$F$2000,$D$6,Base_Dados!$G$3:$G$2000,$D$7,Base_Dados!$H$3:$H$2000,A19,Base_Dados!$I$3:$I$2000,$D$9),0) -> 1 | E19: =IFERROR(AVERAGEIFS(Base_Dados!$O$3:$O$2000,Base_Dados!$B$3:$B$2000,">="&$D$4,Base_Dados!$B$3:$B$2000,"<="&$D$5,Base_Dados!$F$3:$F$2000,$D$6,Base_Dados!$G$3:$G$2000,$D$7,Base_Dados!$H$3:$H$2000,A19,Base_Dados!$I$3:$I$2000,$D$9),0) -> 0 | F19: =IFERROR(AVERAGEIFS(Base_Dados!$U$3:$U$2000,Base_Dados!$B$3:$B$2000,">="&$D$4,Base_Dados!$B$3:$B$2000,"<="&$D$5,Base_Dados!$F$3:$F$2000,$D$6,Base_Dados!$G$3:$G$2000,$D$7,Base_Dados!$H$3:$H$2000,A19,Base_Dados!$I$3:$I$2000,$D$9,Base_Dados!$P$3:$P$2000,$D$10),0) -> 0
A20: Fabiane Almeida | B20: =COUNTIFS(Base_Dados!$B$3:$B$2000,">="&$D$4,Base_Dados!$B$3:$B$2000,"<="&$D$5,Base_Dados!$F$3:$F$2000,$D$6,Base_Dados!$G$3:$G$2000,D13,Base_Dados!$H$3:$H$2000,A20,Base_Dados!$I$3:$I$2000,$D$9) -> 0 | C20: =SUMIFS(Base_Dados!$L$3:$L$2000,Base_Dados!$B$3:$B$2000,">="&$D$4,Base_Dados!$B$3:$B$2000,"<="&$D$5,Base_Dados!$F$3:$F$2000,$D$6,Base_Dados!$G$3:$G$2000,$D$7,Base_Dados!$H$3:$H$2000,A20,Base_Dados!$I$3:$I$2000,$D$9) -> 0 | D20: =IFERROR(SUMIFS(Base_Dados!$L$3:$L$2000,Base_Dados!$B$3:$B$2000,">="&$D$4,Base_Dados!$B$3:$B$2000,"<="&$D$5,Base_Dados!$F$3:$F$2000,$D$6,Base_Dados!$G$3:$G$2000,$D$7,Base_Dados!$H$3:$H$2000,A20,Base_Dados!$I$3:$I$2000,$D$9)/SUMIFS(Base_Dados!$K$3:$K$2000,Base_Dados!$B$3:$B$2000,">="&$D$4,Base_Dados!$B$3:$B$2000,"<="&$D$5,Base_Dados!$F$3:$F$2000,$D$6,Base_Dados!$G$3:$G$2000,$D$7,Base_Dados!$H$3:$H$2000,A20,Base_Dados!$I$3:$I$2000,$D$9),0) -> 0 | E20: =IFERROR(AVERAGEIFS(Base_Dados!$O$3:$O$2000,Base_Dados!$B$3:$B$2000,">="&$D$4,Base_Dados!$B$3:$B$2000,"<="&$D$5,Base_Dados!$F$3:$F$2000,$D$6,Base_Dados!$G$3:$G$2000,$D$7,Base_Dados!$H$3:$H$2000,A20,Base_Dados!$I$3:$I$2000,$D$9),0) -> 0 | F20: =IFERROR(AVERAGEIFS(Base_Dados!$U$3:$U$2000,Base_Dados!$B$3:$B$2000,">="&$D$4,Base_Dados!$B$3:$B$2000,"<="&$D$5,Base_Dados!$F$3:$F$2000,$D$6,Base_Dados!$G$3:$G$2000,$D$7,Base_Dados!$H$3:$H$2000,A20,Base_Dados!$I$3:$I$2000,$D$9,Base_Dados!$P$3:$P$2000,$D$10),0) -> 0
A21: Sarah Almeida | B21: =COUNTIFS(Base_Dados!$B$3:$B$2000,">="&$D$4,Base_Dados!$B$3:$B$2000,"<="&$D$5,Base_Dados!$F$3:$F$2000,$D$6,Base_Dados!$G$3:$G$2000,D14,Base_Dados!$H$3:$H$2000,A21,Base_Dados!$I$3:$I$2000,$D$9) -> 0 | C21: =SUMIFS(Base_Dados!$L$3:$L$2000,Base_Dados!$B$3:$B$2000,">="&$D$4,Base_Dados!$B$3:$B$2000,"<="&$D$5,Base_Dados!$F$3:$F$2000,$D$6,Base_Dados!$G$3:$G$2000,$D$7,Base_Dados!$H$3:$H$2000,A21,Base_Dados!$I$3:$I$2000,$D$9) -> 29 | D21: =IFERROR(SUMIFS(Base_Dados!$L$3:$L$2000,Base_Dados!$B$3:$B$2000,">="&$D$4,Base_Dados!$B$3:$B$2000,"<="&$D$5,Base_Dados!$F$3:$F$2000,$D$6,Base_Dados!$G$3:$G$2000,$D$7,Base_Dados!$H$3:$H$2000,A21,Base_Dados!$I$3:$I$2000,$D$9)/SUMIFS(Base_Dados!$K$3:$K$2000,Base_Dados!$B$3:$B$2000,">="&$D$4,Base_Dados!$B$3:$B$2000,"<="&$D$5,Base_Dados!$F$3:$F$2000,$D$6,Base_Dados!$G$3:$G$2000,$D$7,Base_Dados!$H$3:$H$2000,A21,Base_Dados!$I$3:$I$2000,$D$9),0) -> 1 | E21: =IFERROR(AVERAGEIFS(Base_Dados!$O$3:$O$2000,Base_Dados!$B$3:$B$2000,">="&$D$4,Base_Dados!$B$3:$B$2000,"<="&$D$5,Base_Dados!$F$3:$F$2000,$D$6,Base_Dados!$G$3:$G$2000,$D$7,Base_Dados!$H$3:$H$2000,A21,Base_Dados!$I$3:$I$2000,$D$9),0) -> 0 | F21: =IFERROR(AVERAGEIFS(Base_Dados!$U$3:$U$2000,Base_Dados!$B$3:$B$2000,">="&$D$4,Base_Dados!$B$3:$B$2000,"<="&$D$5,Base_Dados!$F$3:$F$2000,$D$6,Base_Dados!$G$3:$G$2000,$D$7,Base_Dados!$H$3:$H$2000,A21,Base_Dados!$I$3:$I$2000,$D$9,Base_Dados!$P$3:$P$2000,$D$10),0) -> 0
A22: Alessandra Ferreira | B22: =COUNTIFS(Base_Dados!$B$3:$B$2000,">="&$D$4,Base_Dados!$B$3:$B$2000,"<="&$D$5,Base_Dados!$F$3:$F$2000,$D$6,Base_Dados!$G$3:$G$2000,D15,Base_Dados!$H$3:$H$2000,A22,Base_Dados!$I$3:$I$2000,$D$9) -> 0 | C22: =SUMIFS(Base_Dados!$L$3:$L$2000,Base_Dados!$B$3:$B$2000,">="&$D$4,Base_Dados!$B$3:$B$2000,"<="&$D$5,Base_Dados!$F$3:$F$2000,$D$6,Base_Dados!$G$3:$G$2000,$D$7,Base_Dados!$H$3:$H$2000,A22,Base_Dados!$I$3:$I$2000,$D$9) -> 223 | D22: =IFERROR(SUMIFS(Base_Dados!$L$3:$L$2000,Base_Dados!$B$3:$B$2000,">="&$D$4,Base_Dados!$B$3:$B$2000,"<="&$D$5,Base_Dados!$F$3:$F$2000,$D$6,Base_Dados!$G$3:$G$2000,$D$7,Base_Dados!$H$3:$H$2000,A22,Base_Dados!$I$3:$I$2000,$D$9)/SUMIFS(Base_Dados!$K$3:$K$2000,Base_Dados!$B$3:$B$2000,">="&$D$4,Base_Dados!$B$3:$B$2000,"<="&$D$5,Base_Dados!$F$3:$F$2000,$D$6,Base_Dados!$G$3:$G$2000,$D$7,Base_Dados!$H$3:$H$2000,A22,Base_Dados!$I$3:$I$2000,$D$9),0) -> 1 | E22: =IFERROR(AVERAGEIFS(Base_Dados!$O$3:$O$2000,Base_Dados!$B$3:$B$2000,">="&$D$4,Base_Dados!$B$3:$B$2000,"<="&$D$5,Base_Dados!$F$3:$F$2000,$D$6,Base_Dados!$G$3:$G$2000,$D$7,Base_Dados!$H$3:$H$2000,A22,Base_Dados!$I$3:$I$2000,$D$9),0) -> 0 | F22: =IFERROR(AVERAGEIFS(Base_Dados!$U$3:$U$2000,Base_Dados!$B$3:$B$2000,">="&$D$4,Base_Dados!$B$3:$B$2000,"<="&$D$5,Base_Dados!$F$3:$F$2000,$D$6,Base_Dados!$G$3:$G$2000,$D$7,Base_Dados!$H$3:$H$2000,A22,Base_Dados!$I$3:$I$2000,$D$9,Base_Dados!$P$3:$P$2000,$D$10),0) -> 0
A23: Wilze Oliveira | B23: =COUNTIFS(Base_Dados!$B$3:$B$2000,">="&$D$4,Base_Dados!$B$3:$B$2000,"<="&$D$5,Base_Dados!$F$3:$F$2000,$D$6,Base_Dados!$G$3:$G$2000,D16,Base_Dados!$H$3:$H$2000,A23,Base_Dados!$I$3:$I$2000,$D$9) -> 0 | C23: =SUMIFS(Base_Dados!$L$3:$L$2000,Base_Dados!$B$3:$B$2000,">="&$D$4,Base_Dados!$B$3:$B$2000,"<="&$D$5,Base_Dados!$F$3:$F$2000,$D$6,Base_Dados!$G$3:$G$2000,$D$7,Base_Dados!$H$3:$H$2000,A23,Base_Dados!$I$3:$I$2000,$D$9) -> 34 | D23: =IFERROR(SUMIFS(Base_Dados!$L$3:$L$2000,Base_Dados!$B$3:$B$2000,">="&$D$4,Base_Dados!$B$3:$B$2000,"<="&$D$5,Base_Dados!$F$3:$F$2000,$D$6,Base_Dados!$G$3:$G$2000,$D$7,Base_Dados!$H$3:$H$2000,A23,Base_Dados!$I$3:$I$2000,$D$9)/SUMIFS(Base_Dados!$K$3:$K$2000,Base_Dados!$B$3:$B$2000,">="&$D$4,Base_Dados!$B$3:$B$2000,"<="&$D$5,Base_Dados!$F$3:$F$2000,$D$6,Base_Dados!$G$3:$G$2000,$D$7,Base_Dados!$H$3:$H$2000,A23,Base_Dados!$I$3:$I$2000,$D$9),0) -> 1 | E23: =IFERROR(AVERAGEIFS(Base_Dados!$O$3:$O$2000,Base_Dados!$B$3:$B$2000,">="&$D$4,Base_Dados!$B$3:$B$2000,"<="&$D$5,Base_Dados!$F$3:$F$2000,$D$6,Base_Dados!$G$3:$G$2000,$D$7,Base_Dados!$H$3:$H$2000,A23,Base_Dados!$I$3:$I$2000,$D$9),0) -> 0 | F23: =IFERROR(AVERAGEIFS(Base_Dados!$U$3:$U$2000,Base_Dados!$B$3:$B$2000,">="&$D$4,Base_Dados!$B$3:$B$2000,"<="&$D$5,Base_Dados!$F$3:$F$2000,$D$6,Base_Dados!$G$3:$G$2000,$D$7,Base_Dados!$H$3:$H$2000,A23,Base_Dados!$I$3:$I$2000,$D$9,Base_Dados!$P$3:$P$2000,$D$10),0) -> 0
